Workbook

Sheet Crimac
B1: S.No. | C1: Police Station | D1: Total no. of Logins
B2: 1 | C2: Atkuru | D2: 87
B3: 2 | C3: AVANIGADDA | D3: 321
B4: 3 | C4: Bandar Taluk PS | D4: 6673
B5: 4 | C5: Bandar Traffic | D5: 734
B6: 5 | C6: BANTUMILLI | D6: 350
B7: 6 | C7: CCS, Gudivada | D7: 234
B8: 7 | C8: CCS, Machilipatnam | D8: 319
B9: 8 | C9: CHALLAPALLI | D9: 3087
B10: 9 | C10: CHILAKALAPUDI UPS | D10: 202
B11: 10 | C11: Gannavaram UPS | D11: 1914
B12: 11 | C12: Gannavaram Traffic | D12: 466
B13: 12 | C13: GHANTASALA | D13: 116 | G13: Chilakalapudi UPS
B14: 13 | C14: GUDIVADA I TOWN UPS | D14: 748 | G14: Gannavaram UPS
B15: 14 | C15: GUDIVADA II TOWN UPS | D15: 771 | G15: Gudivada I Town UPS
B16: 15 | C16: GUDIVADA RURAL | D16: 4085 | G16: Gudivada II Town UPS
B17: 16 | C17: Gudivada Traffic | D17: 31985 | G17: Inaguduru UPS
B18: 17 | C18: GUDLAVALLERU | D18: 243 | G18: Penamaluru UPS
B19: 18 | C19: GUDURU | D19: 185 | G19: Vuyyuru Town UPS
B20: 19 | C20: HANUMAN JUNCTION | D20: 334
B21: 20 | C21: INAGUDURU UPS | D21: 451
B22: 21 | C22: Kankipadu | D22: 1181
B23: 22 | C23: KODURU | D23: 169
B24: 23 | C24: KRUTHIVENNU | D24: 421
B25: 24 | C25: KUCHIPUDI | D25: 81
B26: 25 | C26: Machilipatnam Town | D26: 257
B27: 26 | C27: Mahila UPS, Machilipatnam | D27: 335
B28: 27 | C28: NAGAYALANKA | D28: 181
B29: 28 | C29: NANDIVADA | D29: 4098
B30: 29 | C30: PAMARRU | D30: 3200
B31: 30 | C31: Pamidimukkala | D31: 4238
... B40: 39 | C40: Vuyyuru Town UPS | D40: 193

Sheet ICJS
A1: SLNo. | B1: District | C1: Police Station | D1: User Level | E1: User Type | F1: User Name | G1: Login Id | H1: Email Id | I1: Last Login Date | J1: Total Login | L1: Row Labels | M1: Sum of Total Login
A2: 1 | B2: KRISHNA | C2: CHILAKALAPUDI UPS | D2: Police Station | E2: Police User | F2: SHO Chilakalapudi | G2: sho_chpd_kri | H2: sho_chpd@kri.appolice.gov.in | I2: 46176.91 | J2: 42 | L2: CHILAKALAPUDI UPS | M2: 42
A3: 2 | B3: KRISHNA | C3: GUDLAVALLERU | D3: Police Station | E3: Police User | F3: SHO Gudlavalleru | G3: sho_gdlv_kri | H3: sho_gdlv@kri.appolice.gov.in | I3: 46175.401 | J3: 2 | L3: GUDLAVALLERU | M3: 2
A4: 3 | B4: KRISHNA | C4: HANUMAN JUNCTION | D4: Police Station | E4: Police User | F4: SHO H.Junction | G4: sho_hjn_kri | H4: sho_hjn@kri.appolice.gov.in | I4: 46181.896 | J4: 2 | L4: HANUMAN JUNCTION | M4: 2
A5: 4 | B5: KRISHNA | C5: Kankipadu | D5: Police Station | E5: Police User | F5: SHO KANKIPADU | G5: sho_kkp_kri | H5: sho_kkp@vza.appolice.gov.in | I5: 46176.441 | J5: 2 | L5: Machilipatnam Town | M5: 67
A6: 5 | B6: KRISHNA | C6: KRUTHIVENNU | D6: Police Station | E6: Police User | F6: SHO Kruttivennu | G6: sho_ktvn_kri | H6: sho_ktvn@kri.appolice.gov.in | I6: 46182.728 | J6: 2 | L6: Pamidimukkala | M6: 4
A7: 6 | B7: KRISHNA | C7: Machilipatnam Town | D7: Police Station | E7: Police User | F7: Beeram Srinivasarao | G7: B_14113404 | H7: srinivasaraobeeram948@gmail.com | I7: 46174.918 | J7: 67 | L7: PEDAPARUPUDI | M7: 35
A8: 7 | B8: KRISHNA | C8: Pamidimukkala | D8: Police Station | E8: Police User | F8: S SIVA NAGESWARA RAO | G8: PC_SIVA_2428 | H8: sarikakrishnaveni999@gmail.com | I8: 46182.895 | J8: 4 | L8: Unguturu | M8: 2
A9: 8 | B9: KRISHNA | C9: PEDAPARUPUDI | D9: Police Station | E9: Police User | F9: SHO Pedaparupudi | G9: sho_pdpp_kri | H9: sho_pdpp@kri.appolice.gov.in | I9: 46182.87 | J9: 35 | L9: (blank)
A10: 9 | B10: KRISHNA | C10: Unguturu | D10: Police Station | E10: Police User | F10: SHO UNGUTURU | G10: sho_ugt_kri | H10: sho_ugt@vza.appolice.gov.in | I10: 46178.508 | J10: 2 | L10: Kankipadu | M10: 2
L11: KRUTHIVENNU | M11: 2
L12: Grand Total | M12: 158

Sheet Sheet1
A1: CriMAC alerts uploaded information: 04-06-2026 To 09-06-2026
A2: S.No. | B2: Police Station | C2: Registered FIRs | D2: Major Heinous Crimes | E2: Notorious Criminals (Arrested / Wanted) | F2: Important Seizure / Recoveries | G2: Jail Releases of Notorious Criminals | H2: Jail Breaks | I2: Major Human Trafficking Recoveries | J2: High Alerts / Hue & Cry Notices | K2: Total no. of Alerts | L2: Ranking (FIRs/ Total Alerts)
A3: 1 | B3: PAMIDIMUKKALA | C3: 29 | D3: =VLOOKUP(B3,Sheet2!F$2:N50,2,0) -> 1389 | E3: =VLOOKUP(B3,Sheet2!F$2:N50,3,0) -> 1055 | F3: =VLOOKUP(B3,Sheet2!F$2:N50,4,0) -> 482 | G3: =VLOOKUP(B3,Sheet2!F$2:N50,5,0) -> 0 | H3: =VLOOKUP(B3,Sheet2!F$2:N50,6,0) -> 0 | I3: =VLOOKUP(B3,Sheet2!F$2:N50,7,0) -> 0 | J3: =VLOOKUP(B3,Sheet2!F$2:N50,8,0) -> 1444 | K3: =SUM(D3:J3) -> 4370 | L3: =K3/C3 -> 150.68966
A4: 2 | B4: GUDIVADA RURAL | C4: 22 | D4: =VLOOKUP(B4,Sheet2!F$2:N42,2,0) -> 2344 | E4: =VLOOKUP(B4,Sheet2!F$2:N42,3,0) -> 0 | F4: =VLOOKUP(B4,Sheet2!F$2:N42,4,0) -> 69 | G4: =VLOOKUP(B4,Sheet2!F$2:N42,5,0) -> 0 | H4: =VLOOKUP(B4,Sheet2!F$2:N42,6,0) -> 0 | I4: =VLOOKUP(B4,Sheet2!F$2:N42,7,0) -> 0 | J4: =VLOOKUP(B4,Sheet2!F$2:N42,8,0) -> 1439 | K4: =SUM(D4:J4) -> 3852 | L4: =K4/C4 -> 175.09091
A5: 3 | B5: VUYYURU RURAL | C5: 17 | D5: =VLOOKUP(B5,Sheet2!F$2:N41,2,0) -> 1520 | E5: =VLOOKUP(B5,Sheet2!F$2:N41,3,0) -> 0 | F5: =VLOOKUP(B5,Sheet2!F$2:N41,4,0) -> 0 | G5: =VLOOKUP(B5,Sheet2!F$2:N41,5,0) -> 0 | H5: =VLOOKUP(B5,Sheet2!F$2:N41,6,0) -> 0 | I5: =VLOOKUP(B5,Sheet2!F$2:N41,7,0) -> 0 | J5: =VLOOKUP(B5,Sheet2!F$2:N41,8,0) -> 651 | K5: =SUM(D5:J5) -> 2171 | L5: =K5/C5 -> 127.70588
A6: 4 | B6: ROBERTSONPET | C6: 33 | D6: =VLOOKUP(B6,Sheet2!F$2:N47,2,0) -> 185 | E6: =VLOOKUP(B6,Sheet2!F$2:N47,3,0) -> 0 | F6: =VLOOKUP(B6,Sheet2!F$2:N47,4,0) -> 0 | G6: =VLOOKUP(B6,Sheet2!F$2:N47,5,0) -> 0 | H6: =VLOOKUP(B6,Sheet2!F$2:N47,6,0) -> 0 | I6: =VLOOKUP(B6,Sheet2!F$2:N47,7,0) -> 0 | J6: =VLOOKUP(B6,Sheet2!F$2:N47,8,0) -> 1848 | K6: =SUM(D6:J6) -> 2033 | L6: =K6/C6 -> 61.606061
A7: 5 | B7: MACHILIPATNAM TOWN | C7: 32 | D7: =VLOOKUP(B7,Sheet2!F$2:N71,2,0) -> 273 | E7: =VLOOKUP(B7,Sheet2!F$2:N71,3,0) -> 1556 | F7: =VLOOKUP(B7,Sheet2!F$2:N71,4,0) -> 0 | G7: =VLOOKUP(B7,Sheet2!F$2:N71,5,0) -> 0 | H7: =VLOOKUP(B7,Sheet2!F$2:N71,6,0) -> 0 | I7: =VLOOKUP(B7,Sheet2!F$2:N71,7,0) -> 50 | J7: =VLOOKUP(B7,Sheet2!F$2:N71,8,0) -> 0 | K7: =SUM(D7:J7) -> 1879 | L7: =K7/C7 -> 58.71875
A8: 6 | B8: NANDIVADA | C8: 19 | D8: =VLOOKUP(B8,Sheet2!F$2:N43,2,0) -> 594 | E8: =VLOOKUP(B8,Sheet2!F$2:N43,3,0) -> 46 | F8: =VLOOKUP(B8,Sheet2!F$2:N43,4,0) -> 32 | G8: =VLOOKUP(B8,Sheet2!F$2:N43,5,0) -> 0 | H8: =VLOOKUP(B8,Sheet2!F$2:N43,6,0) -> 0 | I8: =VLOOKUP(B8,Sheet2!F$2:N43,7,0) -> 0 | J8: =VLOOKUP(B8,Sheet2!F$2:N43,8,0) -> 575 | K8: =SUM(D8:J8) -> 1247 | L8: =K8/C8 -> 65.631579
A9: 7 | B9: CHALLAPALLI | C9: 35 | D9: =VLOOKUP(B9,Sheet2!F$2:N48,2,0) -> 417 | E9: =VLOOKUP(B9,Sheet2!F$2:N48,3,0) -> 22 | F9: =VLOOKUP(B9,Sheet2!F$2:N48,4,0) -> 49 | G9: =VLOOKUP(B9,Sheet2!F$2:N48,5,0) -> 0 | H9: =VLOOKUP(B9,Sheet2!F$2:N48,6,0) -> 0 | I9: =VLOOKUP(B9,Sheet2!F$2:N48,7,0) -> 604 | J9: =VLOOKUP(B9,Sheet2!F$2:N48,8,0) -> 0 | K9: =SUM(D9:J9) -> 1092 | L9: =K9/C9 -> 31.2
A10: 8 | B10: KRUTHIVENNU | C10: 24 | D10: =VLOOKUP(B10,Sheet2!F$2:N63,2,0) -> 0 | E10: =VLOOKUP(B10,Sheet2!F$2:N63,3,0) -> 0 | F10: =VLOOKUP(B10,Sheet2!F$2:N63,4,0) -> 0 | G10: =VLOOKUP(B10,Sheet2!F$2:N63,5,0) -> 734 | H10: =VLOOKUP(B10,Sheet2!F$2:N63,6,0) -> 0 | I10: =VLOOKUP(B10,Sheet2!F$2:N63,7,0) -> 0 | J10: =VLOOKUP(B10,Sheet2!F$2:N63,8,0) -> 70 | K10: =SUM(D10:J10) -> 804 | L10: =K10/C10 -> 33.5
A11: 9 | B11: THOTLAVALLURU | C11: 21 | D11: =VLOOKUP(B11,Sheet2!F$2:N52,2,0) -> 0 | E11: =VLOOKUP(B11,Sheet2!F$2:N52,3,0) -> 733 | F11: =VLOOKUP(B11,Sheet2!F$2:N52,4,0) -> 0 | G11: =VLOOKUP(B11,Sheet2!F$2:N52,5,0) -> 0 | H11: =VLOOKUP(B11,Sheet2!F$2:N52,6,0) -> 0 | I11: =VLOOKUP(B11,Sheet2!F$2:N52,7,0) -> 0 | J11: =VLOOKUP(B11,Sheet2!F$2:N52,8,0) -> 0 | K11: =SUM(D11:J11) -> 733 | L11: =K11/C11 -> 34.904762
A12: 10 | B12: GUDIVADA II TOWN UPS | C12: 28 | D12: =VLOOKUP(B12,Sheet2!F$2:N44,2,0) -> 0 | E12: =VLOOKUP(B12,Sheet2!F$2:N44,3,0) -> 508 | F12: =VLOOKUP(B12,Sheet2!F$2:N44,4,0) -> 0 | G12: =VLOOKUP(B12,Sheet2!F$2:N44,5,0) -> 0 | H12: =VLOOKUP(B12,Sheet2!F$2:N44,6,0) -> 0 | I12: =VLOOKUP(B12,Sheet2!F$2:N44,7,0) -> 0 | J12: =VLOOKUP(B12,Sheet2!F$2:N44,8,0) -> 0 | K12: =SUM(D12:J12) -> 508 | L12: =K12/C12 -> 18.142857
A13: 11 | B13: HANUMAN JUNCTION | C13: 32 | D13: =VLOOKUP(B13,Sheet2!F$2:N49,2,0) -> 0 | E13: =VLOOKUP(B13,Sheet2!F$2:N49,3,0) -> 0 | F13: =VLOOKUP(B13,Sheet2!F$2:N49,4,0) -> 0 | G13: =VLOOKUP(B13,Sheet2!F$2:N49,5,0) -> 0 | H13: =VLOOKUP(B13,Sheet2!F$2:N49,6,0) -> 0 | I13: =VLOOKUP(B13,Sheet2!F$2:N49,7,0) -> 0 | J13: =VLOOKUP(B13,Sheet2!F$2:N49,8,0) -> 432 | K13: =SUM(D13:J13) -> 432 | L13: =K13/C13 -> 13.5
A14: 12 | B14: PEDANA | C14: 25 | D14: =VLOOKUP(B14,Sheet2!F$2:N66,2,0) -> 41 | E14: =VLOOKUP(B14,Sheet2!F$2:N66,3,0) -> 0 | F14: =VLOOKUP(B14,Sheet2!F$2:N66,4,0) -> 0 | G14: =VLOOKUP(B14,Sheet2!F$2:N66,5,0) -> 0 | H14: =VLOOKUP(B14,Sheet2!F$2:N66,6,0) -> 0 | I14: =VLOOKUP(B14,Sheet2!F$2:N66,7,0) -> 0 | J14: =VLOOKUP(B14,Sheet2!F$2:N66,8,0) -> 364 | K14: =SUM(D14:J14) -> 405 | L14: =K14/C14 -> 16.2
A15: 13 | B15: VUYYURU TOWN UPS | C15: 20 | D15: =VLOOKUP(B15,Sheet2!F$2:N46,2,0) -> 245 | E15: =VLOOKUP(B15,Sheet2!F$2:N46,3,0) -> 5 | F15: =VLOOKUP(B15,Sheet2!F$2:N46,4,0) -> 0 | G15: =VLOOKUP(B15,Sheet2!F$2:N46,5,0) -> 0 | H15: =VLOOKUP(B15,Sheet2!F$2:N46,6,0) -> 0 | I15: =VLOOKUP(B15,Sheet2!F$2:N46,7,0) -> 0 | J15: =VLOOKUP(B15,Sheet2!F$2:N46,8,0) -> 97 | K15: =SUM(D15:J15) -> 347 | L15: =K15/C15 -> 17.35
A16: 14 | B16: BANTUMILLI | C16: 31 | D16: =VLOOKUP(B16,Sheet2!F$2:N58,2,0) -> 0 | E16: =VLOOKUP(B16,Sheet2!F$2:N58,3,0) -> 0 | F16: =VLOOKUP(B16,Sheet2!F$2:N58,4,0) -> 0 | G16: =VLOOKUP(B16,Sheet2!F$2:N58,5,0) -> 0 | H16: =VLOOKUP(B16,Sheet2!F$2:N58,6,0) -> 0 | I16: =VLOOKUP(B16,Sheet2!F$2:N58,7,0) -> 0 | J16: =VLOOKUP(B16,Sheet2!F$2:N58,8,0) -> 346 | K16: =SUM(D16:J16) -> 346 | L16: =K16/C16 -> 11.16129
A17: 15 | B17: PEDAPARUPUDI | C17: 20 | D17: =VLOOKUP(B17,Sheet2!F$2:N67,2,0) -> 0 | E17: =VLOOKUP(B17,Sheet2!F$2:N67,3,0) -> 0 | F17: =VLOOKUP(B17,Sheet2!F$2:N67,4,0) -> 0 | G17: =VLOOKUP(B17,Sheet2!F$2:N67,5,0) -> 0 | H17: =VLOOKUP(B17,Sheet2!F$2:N67,6,0) -> 0 | I17: =VLOOKUP(B17,Sheet2!F$2:N67,7,0) -> 0 | J17: =VLOOKUP(B17,Sheet2!F$2:N67,8,0) -> 295 | K17: =SUM(D17:J17) -> 295 | L17: =K17/C17 -> 14.75
A18: 16 | B18: CHILAKALAPUDI UPS | C18: 34 | D18: =VLOOKUP(B18,Sheet2!F$2:N53,2,0) -> 92 | E18: =VLOOKUP(B18,Sheet2!F$2:N53,3,0) -> 0 | F18: =VLOOKUP(B18,Sheet2!F$2:N53,4,0) -> 0 | G18: =VLOOKUP(B18,Sheet2!F$2:N53,5,0) -> 0 | H18: =VLOOKUP(B18,Sheet2!F$2:N53,6,0) -> 0 | I18: =VLOOKUP(B18,Sheet2!F$2:N53,7,0) -> 0 | J18: =VLOOKUP(B18,Sheet2!F$2:N53,8,0) -> 201 | K18: =SUM(D18:J18) -> 293 | L18: =K18/C18 -> 8.6176471
A19: 17 | B19: BANDAR TALUK PS | C19: 26 | D19: =VLOOKUP(B19,Sheet2!F$2:N40,2,0) -> 0 | E19: =VLOOKUP(B19,Sheet2!F$2:N40,3,0) -> 0 | F19: =VLOOKUP(B19,Sheet2!F$2:N40,4,0) -> 0 | G19: =VLOOKUP(B19,Sheet2!F$2:N40,5,0) -> 0 | H19: =VLOOKUP(B19,Sheet2!F$2:N40,6,0) -> 0 | I19: =VLOOKUP(B19,Sheet2!F$2:N40,7,0) -> 0 | J19: =VLOOKUP(B19,Sheet2!F$2:N40,8,0) -> 286 | K19: =SUM(D19:J19) -> 286 | L19: =K19/C19 -> 11
A20: 18 | B20: GUDLAVALLERU | C20: 18 | D20: =VLOOKUP(B20,Sheet2!F$2:N59,2,0) -> 0 | E20: =VLOOKUP(B20,Sheet2!F$2:N59,3,0) -> 263 | F20: =VLOOKUP(B20,Sheet2!F$2:N59,4,0) -> 0 | G20: =VLOOKUP(B20,Sheet2!F$2:N59,5,0) -> 0 | H20: =VLOOKUP(B20,Sheet2!F$2:N59,6,0) -> 0 | I20: =VLOOKUP(B20,Sheet2!F$2:N59,7,0) -> 0 | J20: =VLOOKUP(B20,Sheet2!F$2:N59,8,0) -> 0 | K20: =SUM(D20:J20) -> 263 | L20: =K20/C20 -> 14.611111
A21: 19 | B21: CCS, Machilipatnam | D21: =VLOOKUP(B21,Sheet2!F$2:N71,2,0) -> 0 | E21: =VLOOKUP(B21,Sheet2!F$2:N71,3,0) -> 0 | F21: =VLOOKUP(B21,Sheet2!F$2:N71,4,0) -> 0 | G21: =VLOOKUP(B21,Sheet2!F$2:N71,5,0) -> 0 | H21: =VLOOKUP(B21,Sheet2!F$2:N71,6,0) -> 0 | I21: =VLOOKUP(B21,Sheet2!F$2:N71,7,0) -> 0 | J21: =VLOOKUP(B21,Sheet2!F$2:N71,8,0) -> 235 | K21: =SUM(D21:J21) -> 235 | L21: =K21/C21 -> #DIV/0!
A22: 20 | B22: NAGAYALANKA | C22: 13 | D22: =VLOOKUP(B22,Sheet2!F$2:N65,2,0) -> 133 | E22: =VLOOKUP(B22,Sheet2!F$2:N65,3,0) -> 0 | F22: =VLOOKUP(B22,Sheet2!F$2:N65,4,0) -> 0 | G22: =VLOOKUP(B22,Sheet2!F$2:N65,5,0) -> 0 | H22: =VLOOKUP(B22,Sheet2!F$2:N65,6,0) -> 0 | I22: =VLOOKUP(B22,Sheet2!F$2:N65,7,0) -> 0 | J22: =VLOOKUP(B22,Sheet2!F$2:N65,8,0) -> 43 | K22: =SUM(D22:J22) -> 176 | L22: =K22/C22 -> 13.538462
A23: 21 | B23: MAHILA UPS, MACHILIPATNAM | C23: 0 | D23: =VLOOKUP(B23,Sheet2!F$2:N64,2,0) -> 0 | E23: =VLOOKUP(B23,Sheet2!F$2:N64,3,0) -> 131 | F23: =VLOOKUP(B23,Sheet2!F$2:N64,4,0) -> 0 | G23: =VLOOKUP(B23,Sheet2!F$2:N64,5,0) -> 0 | H23: =VLOOKUP(B23,Sheet2!F$2:N64,6,0) -> 0 | I23: =VLOOKUP(B23,Sheet2!F$2:N64,7,0) -> 0 | J23: =VLOOKUP(B23,Sheet2!F$2:N64,8,0) -> 40 | K23: =SUM(D23:J23) -> 171 | L23: =K23/C23 -> #DIV/0!
A24: 22 | B24: GHANTASALA | C24: 20 | D24: =VLOOKUP(B24,Sheet2!F$2:N69,2,0) -> 171 | E24: =VLOOKUP(B24,Sheet2!F$2:N69,3,0) -> 0 | F24: =VLOOKUP(B24,Sheet2!F$2:N69,4,0) -> 0 | G24: =VLOOKUP(B24,Sheet2!F$2:N69,5,0) -> 0 | H24: =VLOOKUP(B24,Sheet2!F$2:N69,6,0) -> 0 | I24: =VLOOKUP(B24,Sheet2!F$2:N69,7,0) -> 0 | J24: =VLOOKUP(B24,Sheet2!F$2:N69,8,0) -> 0 | K24: =SUM(D24:J24) -> 171 | L24: =K24/C24 -> 8.55
A25: 23 | B25: AVANIGADDA | C25: 17 | D25: =VLOOKUP(B25,Sheet2!F$2:N57,2,0) -> 0 | E25: =VLOOKUP(B25,Sheet2!F$2:N57,3,0) -> 5 | F25: =VLOOKUP(B25,Sheet2!F$2:N57,4,0) -> 0 | G25: =VLOOKUP(B25,Sheet2!F$2:N57,5,0) -> 0 | H25: =VLOOKUP(B25,Sheet2!F$2:N57,6,0) -> 0 | I25: =VLOOKUP(B25,Sheet2!F$2:N57,7,0) -> 0 | J25: =VLOOKUP(B25,Sheet2!F$2:N57,8,0) -> 159 | K25: =SUM(D25:J25) -> 164 | L25: =K25/C25 -> 9.6470588
A26: 24 | B26: VEERAVALLI | C26: 13 | D26: =VLOOKUP(B26,Sheet2!F$2:N68,2,0) -> 106 | E26: =VLOOKUP(B26,Sheet2!F$2:N68,3,0) -> 20 | F26: =VLOOKUP(B26,Sheet2!F$2:N68,4,0) -> 0 | G26: =VLOOKUP(B26,Sheet2!F$2:N68,5,0) -> 0 | H26: =VLOOKUP(B26,Sheet2!F$2:N68,6,0) -> 0 | I26: =VLOOKUP(B26,Sheet2!F$2:N68,7,0) -> 0 | J26: =VLOOKUP(B26,Sheet2!F$2:N68,8,0) -> 0 | K26: =SUM(D26:J26) -> 126 | L26: =K26/C26 -> 9.6923077
A27: 25 | B27: PENAMALURU UPS | C27: 30 | D27: =VLOOKUP(B27,Sheet2!F$2:N55,2,0) -> 0 | E27: =VLOOKUP(B27,Sheet2!F$2:N55,3,0) -> 0 | F27: =VLOOKUP(B27,Sheet2!F$2:N55,4,0) -> 0 | G27: =VLOOKUP(B27,Sheet2!F$2:N55,5,0) -> 0 | H27: =VLOOKUP(B27,Sheet2!F$2:N55,6,0) -> 0 | I27: =VLOOKUP(B27,Sheet2!F$2:N55,7,0) -> 0 | J27: =VLOOKUP(B27,Sheet2!F$2:N55,8,0) -> 120 | K27: =SUM(D27:J27) -> 120 | L27: =K27/C27 -> 4
A28: 26 | B28: KANKIPADU | C28: 27 | D28: =VLOOKUP(B28,Sheet2!F$2:N73,2,0) -> 17 | E28: =VLOOKUP(B28,Sheet2!F$2:N73,3,0) -> 60 | F28: =VLOOKUP(B28,Sheet2!F$2:N73,4,0) -> 0 | G28: =VLOOKUP(B28,Sheet2!F$2:N73,5,0) -> 0 | H28: =VLOOKUP(B28,Sheet2!F$2:N73,6,0) -> 0 | I28: =VLOOKUP(B28,Sheet2!F$2:N73,7,0) -> 0 | J28: =VLOOKUP(B28,Sheet2!F$2:N73,8,0) -> 37 | K28: =SUM(D28:J28) -> 114 | L28: =K28/C28 -> 4.2222222
A29: 27 | B29: ATKURU | C29: 3 | D29: =VLOOKUP(B29,Sheet2!F$2:N54,2,0) -> 0 | E29: =VLOOKUP(B29,Sheet2!F$2:N54,3,0) -> 0 | F29: =VLOOKUP(B29,Sheet2!F$2:N54,4,0) -> 0 | G29: =VLOOKUP(B29,Sheet2!F$2:N54,5,0) -> 0 | H29: =VLOOKUP(B29,Sheet2!F$2:N54,6,0) -> 0 | I29: =VLOOKUP(B29,Sheet2!F$2:N54,7,0) -> 7 | J29: =VLOOKUP(B29,Sheet2!F$2:N54,8,0) -> 102 | K29: =SUM(D29:J29) -> 109 | L29: =K29/C29 -> 36.333333
A30: 28 | B30: KODURU | C30: 17 | D30: =VLOOKUP(B30,Sheet2!F$2:N62,2,0) -> 0 | E30: =VLOOKUP(B30,Sheet2!F$2:N62,3,0) -> 0 | F30: =VLOOKUP(B30,Sheet2!F$2:N62,4,0) -> 0 | G30: =VLOOKUP(B30,Sheet2!F$2:N62,5,0) -> 0 | H30: =VLOOKUP(B30,Sheet2!F$2:N62,6,0) -> 0 | I30: =VLOOKUP(B30,Sheet2!F$2:N62,7,0) -> 0 | J30: =VLOOKUP(B30,Sheet2!F$2:N62,8,0) -> 104 | K30: =SUM(D30:J30) -> 104 | L30: =K30/C30 -> 6.1176471
A31: 29 | B31: KUCHIPUDI | C31: 6 | D31: =VLOOKUP(B31,Sheet2!F$2:N61,2,0) -> 0 | E31: =VLOOKUP(B31,Sheet2!F$2:N61,3,0) -> 0 | F31: =VLOOKUP(B31,Sheet2!F$2:N61,4,0) -> 0 | G31: =VLOOKUP(B31,Sheet2!F$2:N61,5,0) -> 0 | H31: =VLOOKUP(B31,Sheet2!F$2:N61,6,0) -> 0 | I31: =VLOOKUP(B31,Sheet2!F$2:N61,7,0) -> 0 | J31: =VLOOKUP(B31,Sheet2!F$2:N61,8,0) -> 75 | K31: =SUM(D31:J31) -> 75 | L31: 0
A32: 30 | B32: GUDIVADA I TOWN UPS | C32: 31 | D32: =VLOOKUP(B32,Sheet2!F$2:N45,2,0) -> 0 | E32: =VLOOKUP(B32,Sheet2!F$2:N45,3,0) -> 0 | F32: =VLOOKUP(B32,Sheet2!F$2:N45,4,0) -> 0 | G32: =VLOOKUP(B32,Sheet2!F$2:N45,5,0) -> 0 | H32: =VLOOKUP(B32,Sheet2!F$2:N45,6,0) -> 0 | I32: =VLOOKUP(B32,Sheet2!F$2:N45,7,0) -> 0 | J32: =VLOOKUP(B32,Sheet2!F$2:N45,8,0) -> 69 | K32: =SUM(D32:J32) -> 69 | L32: =K32/C32 -> 2.2258065
A33: 31 | B33: GUDURU | C33: 21 | D33: =VLOOKUP(B33,Sheet2!F$2:N70,2,0) -> 8 | E33: =VLOOKUP(B33,Sheet2!F$2:N70,3,0) -> 0 | F33: =VLOOKUP(B33,Sheet2!F$2:N70,4,0) -> 0 | G33: =VLOOKUP(B33,Sheet2!F$2:N70,5,0) -> 0 | H33: =VLOOKUP(B33,Sheet2!F$2:N70,6,0) -> 0 | I33: =VLOOKUP(B33,Sheet2!F$2:N70,7,0) -> 0 | J33: =VLOOKUP(B33,Sheet2!F$2:N70,8,0) -> 60 | K33: =SUM(D33:J33) -> 68 | L33: =K33/C33 -> 3.2380952
A34: 32 | B34: Gudivada Traffic | D34: =VLOOKUP(B34,Sheet2!F$2:N70,2,0) -> 0 | E34: =VLOOKUP(B34,Sheet2!F$2:N70,3,0) -> 0 | F34: =VLOOKUP(B34,Sheet2!F$2:N70,4,0) -> 0 | G34: =VLOOKUP(B34,Sheet2!F$2:N70,5,0) -> 0 | H34: =VLOOKUP(B34,Sheet2!F$2:N70,6,0) -> 0 | I34: =VLOOKUP(B34,Sheet2!F$2:N70,7,0) -> 0 | J34: =VLOOKUP(B34,Sheet2!F$2:N70,8,0) -> 66 | K34: =SUM(D34:J34) -> 66 | L34: =K34/C34 -> #DIV/0!
A35: 33 | B35: UNGUTURU | C35: 13 | D35: =VLOOKUP(B35,Sheet2!F$2:N51,2,0) -> 66 | E35: =VLOOKUP(B35,Sheet2!F$2:N51,3,0) -> 0 | F35: =VLOOKUP(B35,Sheet2!F$2:N51,4,0) -> 0 | G35: =VLOOKUP(B35,Sheet2!F$2:N51,5,0) -> 0 | H35: =VLOOKUP(B35,Sheet2!F$2:N51,6,0) -> 0 | I35: =VLOOKUP(B35,Sheet2!F$2:N51,7,0) -> 0 | J35: =VLOOKUP(B35,Sheet2!F$2:N51,8,0) -> 0 | K35: =SUM(D35:J35) -> 66 | L35: =K35/C35 -> 5.0769231
A36: 34 | B36: PAMARRU | C36: 22 | D36: =VLOOKUP(B36,Sheet2!F$2:N56,2,0) -> 61 | E36: =VLOOKUP(B36,Sheet2!F$2:N56,3,0) -> 0 | F36: =VLOOKUP(B36,Sheet2!F$2:N56,4,0) -> 0 | G36: =VLOOKUP(B36,Sheet2!F$2:N56,5,0) -> 0 | H36: =VLOOKUP(B36,Sheet2!F$2:N56,6,0) -> 0 | I36: =VLOOKUP(B36,Sheet2!F$2:N56,7,0) -> 0 | J36: =VLOOKUP(B36,Sheet2!F$2:N56,8,0) -> 0 | K36: =SUM(D36:J36) -> 61 | L36: =K36/C36 -> 2.7727273
A37: 35 | B37: GANNAVARAM UPS | C37: 20 | D37: =VLOOKUP(B37,Sheet2!F$2:N72,2,0) -> 0 | E37: =VLOOKUP(B37,Sheet2!F$2:N72,3,0) -> 0 | F37: =VLOOKUP(B37,Sheet2!F$2:N72,4,0) -> 0 | G37: =VLOOKUP(B37,Sheet2!F$2:N72,5,0) -> 0 | H37: =VLOOKUP(B37,Sheet2!F$2:N72,6,0) -> 0 | I37: =VLOOKUP(B37,Sheet2!F$2:N72,7,0) -> 0 | J37: =VLOOKUP(B37,Sheet2!F$2:N72,8,0) -> 60 | K37: =SUM(D37:J37) -> 60
A38: 36 | B38: CCS, Gudivada | D38: =VLOOKUP(B38,Sheet2!F$2:N73,2,0) -> 0 | E38: =VLOOKUP(B38,Sheet2!F$2:N73,3,0) -> 0 | F38: =VLOOKUP(B38,Sheet2!F$2:N73,4,0) -> 0 | G38: =VLOOKUP(B38,Sheet2!F$2:N73,5,0) -> 0 | H38: =VLOOKUP(B38,Sheet2!F$2:N73,6,0) -> 0 | I38: =VLOOKUP(B38,Sheet2!F$2:N73,7,0) -> 0 | J38: =VLOOKUP(B38,Sheet2!F$2:N73,8,0) -> 60 | K38: =SUM(D38:J38) -> 60
A39: 37 | B39: Bandar Traffic | D39: =VLOOKUP(B39,Sheet2!F$2:N74,2,0) -> 0 | E39: =VLOOKUP(B39,Sheet2!F$2:N72,3,0) -> 0 | F39: =VLOOKUP(B39,Sheet2!F$2:N72,4,0) -> 0 | G39: =VLOOKUP(B39,Sheet2!F$2:N72,5,0) -> 0 | H39: =VLOOKUP(B39,Sheet2!F$2:N72,6,0) -> 0 | I39: =VLOOKUP(B39,Sheet2!F$2:N72,7,0) -> 0 | J39: =VLOOKUP(B39,Sheet2!F$2:N72,8,0) -> 60 | K39: =SUM(D39:J39) -> 60
A40: 38 | B40: INAGUDURU UPS | C40: 34 | D40: =VLOOKUP(B40,Sheet2!F$2:N60,2,0) -> 0 | E40: =VLOOKUP(B40,Sheet2!F$2:N60,3,0) -> 0 | F40: =VLOOKUP(B40,Sheet2!F$2:N60,4,0) -> 0 | G40: =VLOOKUP(B40,Sheet2!F$2:N60,5,0) -> 0 | H40: =VLOOKUP(B40,Sheet2!F$2:N60,6,0) -> 0 | I40: =VLOOKUP(B40,Sheet2!F$2:N60,7,0) -> 0 | J40: =VLOOKUP(B40,Sheet2!F$2:N60,8,0) -> 47 | K40: =SUM(D40:J40) -> 47
...

Sheet Sheet2
E2: 1 | F2: AVANIGADDA | G2: 0 | H2: 5 | I2: 0 | J2: 0 | K2: 0 | L2: 0 | M2: 159 | N2: 164
E3: 2 | F3: Bandar Taluk PS | G3: 0 | H3: 0 | I3: 0 | J3: 0 | K3: 0 | L3: 0 | M3: 286 | N3: 286
E4: 3 | F4: BANTUMILLI | G4: 0 | H4: 0 | I4: 0 | J4: 0 | K4: 0 | L4: 0 | M4: 346 | N4: 346
E5: 4 | F5: CHALLAPALLI | G5: 417 | H5: 22 | I5: 49 | J5: 0 | K5: 0 | L5: 604 | M5: 0 | N5: 1092
E6: 5 | F6: CHILAKALAPUDI UPS | G6: 92 | H6: 0 | I6: 0 | J6: 0 | K6: 0 | L6: 0 | M6: 201 | N6: 293
E7: 6 | F7: GUDIVADA RURAL | G7: 2344 | H7: 0 | I7: 69 | J7: 0 | K7: 0 | L7: 0 | M7: 1439 | N7: 3852
E8: 7 | F8: GUDIVADA I TOWN UPS | G8: 0 | H8: 0 | I8: 0 | J8: 0 | K8: 0 | L8: 0 | M8: 69 | N8: 69
E9: 8 | F9: GUDLAVALLERU | G9: 0 | H9: 263 | I9: 0 | J9: 0 | K9: 0 | L9: 0 | M9: 0 | N9: 263
E10: 9 | F10: GUDIVADA II TOWN UPS | G10: 0 | H10: 508 | I10: 0 | J10: 0 | K10: 0 | L10: 0 | M10: 0 | N10: 508
E11: 10 | F11: INAGUDURU UPS | G11: 0 | H11: 0 | I11: 0 | J11: 0 | K11: 0 | L11: 0 | M11: 47 | N11: 47
E12: 11 | F12: HANUMAN JUNCTION | G12: 0 | H12: 0 | I12: 0 | J12: 0 | K12: 0 | L12: 0 | M12: 432 | N12: 432
E13: 12 | F13: KUCHIPUDI | G13: 0 | H13: 0 | I13: 0 | J13: 0 | K13: 0 | L13: 0 | M13: 75 | N13: 75
... E40: 39 | F40: Gannavaram Traffic | G40: 0 | H40: 0 | I40: 0 | J40: 0 | K40: 0 | L40: 0 | M40: 36 | N40: 36
E41: TOTAL NUMBER OF ALERTS | G41: 7662 | H41: 4404 | I41: 632 | J41: 734 | K41: 0 | L41: 661 | M41: 9421 | N41: 23514

Sheet stt
A1: CriMAC Alerts uploaded
A2: S.No. | B2: Police Station | C2: Registered FIRs | D2: Major Heinous Crimes | E2: Notorious Criminals (Arrested / Wanted) | F2: Important Seizure / Recoveries | G2: Jail Releases of Notorious Criminals | H2: Jail Breaks | I2: Major Human Trafficking Recoveries | J2: High Alerts / Hue & Cry Notices | K2: Total no. of Alerts | L2: Ranking (FIRs/ Total Alerts) | N2: 01.04.26 to 07.04.26 | P2: 08.04.26 to 14.04.26 | R2: 15.04.26 to 21.04.26 | T2: 3 Weeks Total
A3: 1 | B3: GUDIVADA II TOWN UPS | C3: =VLOOKUP(B3,'[1]export - 2026-04-25T055159.564 '!$A$1:$B$35,2,0) -> 28 | D3: =VLOOKUP(B3,weeks!F$2:N54,2,0) -> 31 | E3: =VLOOKUP(B3,weeks!F$2:N54,3,0) -> 31 | F3: =VLOOKUP(B3,weeks!F$2:N54,4,0) -> 2 | G3: =VLOOKUP(B3,weeks!F$2:N54,5,0) -> 0 | H3: =VLOOKUP(B3,weeks!F$2:N54,6,0) -> 0 | I3: =VLOOKUP(B3,weeks!F$2:N54,7,0) -> 0 | J3: =VLOOKUP(B3,weeks!F$2:N54,8,0) -> 0 | K3: =SUM(D3:J3) -> 64 | L3: =K3/C3 -> 2.2857143 | N3: 8 | O3: 2.6666667 | P3: 96 | Q3: 24 | R3: 64 | S3: 2.2857143 | T3: =SUM(N3,P3,R3) -> 168
A4: 2 | B4: VUYYURU RURAL | C4: =VLOOKUP(B4,'[1]export - 2026-04-25T055159.564 '!$A$1:$B$35,2,0) -> 17 | D4: =VLOOKUP(B4,weeks!F$2:N48,2,0) -> 11 | E4: =VLOOKUP(B4,weeks!F$2:N48,3,0) -> 0 | F4: =VLOOKUP(B4,weeks!F$2:N48,4,0) -> 0 | G4: =VLOOKUP(B4,weeks!F$2:N48,5,0) -> 0 | H4: =VLOOKUP(B4,weeks!F$2:N48,6,0) -> 0 | I4: =VLOOKUP(B4,weeks!F$2:N48,7,0) -> 0 | J4: =VLOOKUP(B4,weeks!F$2:N48,8,0) -> 0 | K4: =SUM(D4:J4) -> 11 | L4: =K4/C4 -> 0.64705882 | N4: 10 | O4: 3.3333333 | P4: 29 | Q4: #N/A | R4: 11 | S4: 0.64705882 | T4: =SUM(N4,P4,R4) -> 50
A5: 3 | B5: GUDIVADA RURAL | C5: =VLOOKUP(B5,'[1]export - 2026-04-25T055159.564 '!$A$1:$B$35,2,0) -> 22 | D5: =VLOOKUP(B5,weeks!F$2:N49,2,0) -> 9 | E5: =VLOOKUP(B5,weeks!F$2:N49,3,0) -> 0 | F5: =VLOOKUP(B5,weeks!F$2:N49,4,0) -> 4 | G5: =VLOOKUP(B5,weeks!F$2:N49,5,0) -> 0 | H5: =VLOOKUP(B5,weeks!F$2:N49,6,0) -> 0 | I5: =VLOOKUP(B5,weeks!F$2:N49,7,0) -> 0 | J5: =VLOOKUP(B5,weeks!F$2:N49,8,0) -> 1 | K5: =SUM(D5:J5) -> 14 | L5: =K5/C5 -> 0.63636364 | N5: 13 | O5: 13 | P5: 18 | Q5: 9 | R5: 14 | S5: 0.63636364 | T5: =SUM(N5,P5,R5) -> 45
A6: 4 | B6: PENAMALURU UPS | C6: =VLOOKUP(B6,'[1]export - 2026-04-25T055159.564 '!$A$1:$B$35,2,0) -> 30 | D6: =VLOOKUP(B6,weeks!F$2:N50,2,0) -> 3 | E6: =VLOOKUP(B6,weeks!F$2:N50,3,0) -> 0 | F6: =VLOOKUP(B6,weeks!F$2:N50,4,0) -> 0 | G6: =VLOOKUP(B6,weeks!F$2:N50,5,0) -> 0 | H6: =VLOOKUP(B6,weeks!F$2:N50,6,0) -> 0 | I6: =VLOOKUP(B6,weeks!F$2:N50,7,0) -> 0 | J6: =VLOOKUP(B6,weeks!F$2:N50,8,0) -> 0 | K6: =SUM(D6:J6) -> 3 | L6: =K6/C6 -> 0.1 | N6: 18 | O6: 1.8 | P6: 19 | Q6: 1.1176471 | R6: 3 | S6: 0.1 | T6: =SUM(N6,P6,R6) -> 40
A7: 5 | B7: PEDAPARUPUDI | C7: =VLOOKUP(B7,'[1]export - 2026-04-25T055159.564 '!$A$1:$B$35,2,0) -> 20 | D7: =VLOOKUP(B7,weeks!F$2:N44,2,0) -> 2 | E7: =VLOOKUP(B7,weeks!F$2:N44,3,0) -> 5 | F7: =VLOOKUP(B7,weeks!F$2:N44,4,0) -> 0 | G7: =VLOOKUP(B7,weeks!F$2:N44,5,0) -> 0 | H7: =VLOOKUP(B7,weeks!F$2:N44,6,0) -> 0 | I7: =VLOOKUP(B7,weeks!F$2:N44,7,0) -> 0 | J7: =VLOOKUP(B7,weeks!F$2:N44,8,0) -> 0 | K7: =SUM(D7:J7) -> 7 | L7: =K7/C7 -> 0.35 | N7: 0 | O7: 0 | P7: 23 | Q7: 3.2857143 | R7: 7 | S7: 0.35 | T7: =SUM(N7,P7,R7) -> 30
A8: 6 | B8: VUYYURU TOWN UPS | C8: =VLOOKUP(B8,'[1]export - 2026-04-25T055159.564 '!$A$1:$B$35,2,0) -> 20 | D8: =VLOOKUP(B8,weeks!F$2:N46,2,0) -> 9 | E8: =VLOOKUP(B8,weeks!F$2:N46,3,0) -> 0 | F8: =VLOOKUP(B8,weeks!F$2:N46,4,0) -> 0 | G8: =VLOOKUP(B8,weeks!F$2:N46,5,0) -> 0 | H8: =VLOOKUP(B8,weeks!F$2:N46,6,0) -> 0 | I8: =VLOOKUP(B8,weeks!F$2:N46,7,0) -> 0 | J8: =VLOOKUP(B8,weeks!F$2:N46,8,0) -> 0 | K8: =SUM(D8:J8) -> 9 | L8: =K8/C8 -> 0.45 | N8: 10 | O8: 10 | P8: 11 | Q8: 3.6666667 | R8: 9 | S8: 0.45 | T8: =SUM(N8,P8,R8) -> 30
A9: 7 | B9: BANTUMILLI | C9: =VLOOKUP(B9,'[1]export - 2026-04-25T055159.564 '!$A$1:$B$35,2,0) -> 31 | D9: =VLOOKUP(B9,weeks!F$2:N40,2,0) -> 0 | E9: =VLOOKUP(B9,weeks!F$2:N40,3,0) -> 6 | F9: =VLOOKUP(B9,weeks!F$2:N40,4,0) -> 0 | G9: =VLOOKUP(B9,weeks!F$2:N40,5,0) -> 0 | H9: =VLOOKUP(B9,weeks!F$2:N40,6,0) -> 0 | I9: =VLOOKUP(B9,weeks!F$2:N40,7,0) -> 0 | J9: =VLOOKUP(B9,weeks!F$2:N40,8,0) -> 0 | K9: =SUM(D9:J9) -> 6 | L9: =K9/C9 -> 0.19354839 | N9: 2 | O9: 1 | P9: 19 | Q9: 3.8 | R9: 6 | S9: 0.19354839 | T9: =SUM(N9,P9,R9) -> 27
A10: 8 | B10: CHILAKALAPUDI UPS | C10: =VLOOKUP(B10,'[1]export - 2026-04-25T055159.564 '!$A$1:$B$35,2,0) -> 34 | D10: =VLOOKUP(B10,weeks!F$2:N47,2,0) -> 0 | E10: =VLOOKUP(B10,weeks!F$2:N47,3,0) -> 0 | F10: =VLOOKUP(B10,weeks!F$2:N47,4,0) -> 0 | G10: =VLOOKUP(B10,weeks!F$2:N47,5,0) -> 0 | H10: =VLOOKUP(B10,weeks!F$2:N47,6,0) -> 0 | I10: =VLOOKUP(B10,weeks!F$2:N47,7,0) -> 0 | J10: =VLOOKUP(B10,weeks!F$2:N47,8,0) -> 0 | K10: =SUM(D10:J10) -> 0 | L10: =K10/C10 -> 0 | N10: 19 | O10: 3.8 | P10: 6 | Q10: 2 | R10: 0 | S10: 0 | T10: =SUM(N10,P10,R10) -> 25
A11: 9 | B11: BANDAR TALUK PS | C11: =VLOOKUP(B11,'[1]export - 2026-04-25T055159.564 '!$A$1:$B$35,2,0) -> 26 | D11: =VLOOKUP(B11,weeks!F$2:N66,2,0) -> 0 | E11: =VLOOKUP(B11,weeks!F$2:N66,3,0) -> 0 | F11: =VLOOKUP(B11,weeks!F$2:N66,4,0) -> 0 | G11: =VLOOKUP(B11,weeks!F$2:N66,5,0) -> 0 | H11: =VLOOKUP(B11,weeks!F$2:N66,6,0) -> 0 | I11: =VLOOKUP(B11,weeks!F$2:N66,7,0) -> 0 | J11: =VLOOKUP(B11,weeks!F$2:N66,8,0) -> 0 | K11: =SUM(D11:J11) -> 0 | L11: =K11/C11 -> 0 | N11: 0 | O11: 0 | P11: 24 | Q11: 4.8 | R11: 0 | S11: 0 | T11: =SUM(N11,P11,R11) -> 24
A12: 10 | B12: CHALLAPALLI | C12: =VLOOKUP(B12,'[1]export - 2026-04-25T055159.564 '!$A$1:$B$35,2,0) -> 35 | D12: =VLOOKUP(B12,weeks!F$2:N41,2,0) -> 0 | E12: =VLOOKUP(B12,weeks!F$2:N41,3,0) -> 0 | F12: =VLOOKUP(B12,weeks!F$2:N41,4,0) -> 0 | G12: =VLOOKUP(B12,weeks!F$2:N41,5,0) -> 0 | H12: =VLOOKUP(B12,weeks!F$2:N41,6,0) -> 0 | I12: =VLOOKUP(B12,weeks!F$2:N41,7,0) -> 0 | J12: =VLOOKUP(B12,weeks!F$2:N41,8,0) -> 0 | K12: =SUM(D12:J12) -> 0 | L12: =K12/C12 -> 0 | N12: 14 | O12: 2.3333333 | P12: 0 | Q12: 0 | R12: 0 | S12: 0 | T12: =SUM(N12,P12,R12) -> 14
A13: 11 | B13: INAGUDURU UPS | C13: =VLOOKUP(B13,'[1]export - 2026-04-25T055159.564 '!$A$1:$B$35,2,0) -> 34 | D13: =VLOOKUP(B13,weeks!F$2:N62,2,0) -> 3 | E13: =VLOOKUP(B13,weeks!F$2:N62,3,0) -> 0 | F13: =VLOOKUP(B13,weeks!F$2:N62,4,0) -> 0 | G13: =VLOOKUP(B13,weeks!F$2:N62,5,0) -> 0 | H13: =VLOOKUP(B13,weeks!F$2:N62,6,0) -> 0 | I13: =VLOOKUP(B13,weeks!F$2:N62,7,0) -> 0 | J13: =VLOOKUP(B13,weeks!F$2:N62,8,0) -> 0 | K13: =SUM(D13:J13) -> 3 | L13: =K13/C13 -> 0.088235294 | N13: 1 | O13: 0.33333333 | P13: 5 | Q13: 1.25 | R13: 3 | S13: 0.088235294 | T13: =SUM(N13,P13,R13) -> 9
A14: 12 | B14: ROBERTSONPET | C14: =VLOOKUP(B14,'[1]export - 2026-04-25T055159.564 '!$A$1:$B$35,2,0) -> 33 | D14: =VLOOKUP(B14,weeks!F$2:N65,2,0) -> 0 | E14: =VLOOKUP(B14,weeks!F$2:N65,3,0) -> 0 | F14: =VLOOKUP(B14,weeks!F$2:N65,4,0) -> 0 | G14: =VLOOKUP(B14,weeks!F$2:N65,5,0) -> 0 | H14: =VLOOKUP(B14,weeks!F$2:N65,6,0) -> 0 | I14: =VLOOKUP(B14,weeks!F$2:N65,7,0) -> 0 | J14: =VLOOKUP(B14,weeks!F$2:N65,8,0) -> 0 | K14: =SUM(D14:J14) -> 0 | L14: =K14/C14 -> 0 | N14: 6 | O14: 3 | P14: 3 | Q14: 1.5 | R14: 0 | S14: 0 | T14: =SUM(N14,P14,R14) -> 9
A15: 13 | B15: ATKURU | C15: =VLOOKUP(B15,'[1]export - 2026-04-25T055159.564 '!$A$1:$B$35,2,0) -> 3 | D15: =VLOOKUP(B15,weeks!F$2:N68,2,0) -> 0 | E15: =VLOOKUP(B15,weeks!F$2:N68,3,0) -> 0 | F15: =VLOOKUP(B15,weeks!F$2:N68,4,0) -> 0 | G15: =VLOOKUP(B15,weeks!F$2:N68,5,0) -> 0 | H15: =VLOOKUP(B15,weeks!F$2:N68,6,0) -> 0 | I15: =VLOOKUP(B15,weeks!F$2:N68,7,0) -> 0 | J15: =VLOOKUP(B15,weeks!F$2:N68,8,0) -> 0 | K15: =SUM(D15:J15) -> 0 | L15: 0 | N15: 2 | O15: 0 | P15: 7 | Q15: 0 | R15: 0 | S15: 0 | T15: =SUM(N15,P15,R15) -> 9
A16: 14 | B16: GANNAVARAM UPS | C16: =VLOOKUP(B16,'[1]export - 2026-04-25T055159.564 '!$A$1:$B$35,2,0) -> 20 | D16: =VLOOKUP(B16,weeks!F$2:N56,2,0) -> 0 | E16: =VLOOKUP(B16,weeks!F$2:N56,3,0) -> 0 | F16: =VLOOKUP(B16,weeks!F$2:N56,4,0) -> 0 | G16: =VLOOKUP(B16,weeks!F$2:N56,5,0) -> 0 | H16: =VLOOKUP(B16,weeks!F$2:N56,6,0) -> 0 | I16: =VLOOKUP(B16,weeks!F$2:N56,7,0) -> 0 | J16: =VLOOKUP(B16,weeks!F$2:N56,8,0) -> 2 | K16: =SUM(D16:J16) -> 2 | L16: =K16/C16 -> 0.1 | N16: 3 | O16: 0.5 | P16: 2 | Q16: 0.66666667 | R16: 2 | S16: 0.1 | T16: =SUM(N16,P16,R16) -> 7
A17: 15 | B17: UNGUTURU | C17: =VLOOKUP(B17,'[1]export - 2026-04-25T055159.564 '!$A$1:$B$35,2,0) -> 13 | D17: =VLOOKUP(B17,weeks!F$2:N55,2,0) -> 0 | E17: =VLOOKUP(B17,weeks!F$2:N55,3,0) -> 0 | F17: =VLOOKUP(B17,weeks!F$2:N55,4,0) -> 0 | G17: =VLOOKUP(B17,weeks!F$2:N55,5,0) -> 0 | H17: =VLOOKUP(B17,weeks!F$2:N55,6,0) -> 0 | I17: =VLOOKUP(B17,weeks!F$2:N55,7,0) -> 0 | J17: =VLOOKUP(B17,weeks!F$2:N55,8,0) -> 0 | K17: =SUM(D17:J17) -> 0 | L17: =K17/C17 -> 0 | N17: 5 | O17: #N/A | P17: 0 | Q17: #N/A | R17: 0 | S17: 0 | T17: =SUM(N17,P17,R17) -> 5
A18: 16 | B18: NAGAYALANKA | C18: =VLOOKUP(B18,'[1]export - 2026-04-25T055159.564 '!$A$1:$B$35,2,0) -> 13 | D18: =VLOOKUP(B18,weeks!F$2:N45,2,0) -> 0 | E18: =VLOOKUP(B18,weeks!F$2:N45,3,0) -> 0 | F18: =VLOOKUP(B18,weeks!F$2:N45,4,0) -> 0 | G18: =VLOOKUP(B18,weeks!F$2:N45,5,0) -> 0 | H18: =VLOOKUP(B18,weeks!F$2:N45,6,0) -> 0 | I18: =VLOOKUP(B18,weeks!F$2:N45,7,0) -> 0 | J18: =VLOOKUP(B18,weeks!F$2:N45,8,0) -> 0 | K18: =SUM(D18:J18) -> 0 | L18: =K18/C18 -> 0 | N18: 0 | O18: 0 | P18: 4 | Q18: #DIV/0! | R18: 0 | S18: 0 | T18: =SUM(N18,P18,R18) -> 4
A19: 17 | B19: PAMARRU | C19: =VLOOKUP(B19,'[1]export - 2026-04-25T055159.564 '!$A$1:$B$35,2,0) -> 22 | D19: =VLOOKUP(B19,weeks!F$2:N51,2,0) -> 1 | E19: =VLOOKUP(B19,weeks!F$2:N51,3,0) -> 1 | F19: =VLOOKUP(B19,weeks!F$2:N51,4,0) -> 0 | G19: =VLOOKUP(B19,weeks!F$2:N51,5,0) -> 0 | H19: =VLOOKUP(B19,weeks!F$2:N51,6,0) -> 0 | I19: =VLOOKUP(B19,weeks!F$2:N51,7,0) -> 0 | J19: =VLOOKUP(B19,weeks!F$2:N51,8,0) -> 0 | K19: =SUM(D19:J19) -> 2 | L19: =K19/C19 -> 0.090909091 | N19: 0 | O19: 0 | P19: 2 | Q19: 2 | R19: 2 | S19: 0.090909091 | T19: =SUM(N19,P19,R19) -> 4
A20: 18 | B20: NANDIVADA | C20: =VLOOKUP(B20,'[1]export - 2026-04-25T055159.564 '!$A$1:$B$35,2,0) -> 19 | D20: =VLOOKUP(B20,weeks!F$2:N59,2,0) -> 0 | E20: =VLOOKUP(B20,weeks!F$2:N59,3,0) -> 0 | F20: =VLOOKUP(B20,weeks!F$2:N59,4,0) -> 0 | G20: =VLOOKUP(B20,weeks!F$2:N59,5,0) -> 0 | H20: =VLOOKUP(B20,weeks!F$2:N59,6,0) -> 0 | I20: =VLOOKUP(B20,weeks!F$2:N59,7,0) -> 0 | J20: =VLOOKUP(B20,weeks!F$2:N59,8,0) -> 0 | K20: =SUM(D20:J20) -> 0 | L20: =K20/C20 -> 0 | N20: 3 | O20: #DIV/0! | P20: 0 | Q20: 0 | R20: 0 | S20: 0 | T20: =SUM(N20,P20,R20) -> 3
A21: 19 | B21: GUDLAVALLERU | C21: =VLOOKUP(B21,'[1]export - 2026-04-25T055159.564 '!$A$1:$B$35,2,0) -> 18 | D21: =VLOOKUP(B21,weeks!F$2:N63,2,0) -> 1 | E21: =VLOOKUP(B21,weeks!F$2:N63,3,0) -> 0 | F21: =VLOOKUP(B21,weeks!F$2:N63,4,0) -> 0 | G21: =VLOOKUP(B21,weeks!F$2:N63,5,0) -> 0 | H21: =VLOOKUP(B21,weeks!F$2:N63,6,0) -> 0 | I21: =VLOOKUP(B21,weeks!F$2:N63,7,0) -> 0 | J21: =VLOOKUP(B21,weeks!F$2:N63,8,0) -> 0 | K21: =SUM(D21:J21) -> 1 | L21: =K21/C21 -> 0.055555556 | N21: 1 | O21: 0.5 | P21: 1 | Q21: 1 | R21: 1 | S21: 0.055555556 | T21: =SUM(N21,P21,R21) -> 3
A22: 20 | B22: MACHILIPATNAM TOWN | C22: =VLOOKUP(B22,'[1]export - 2026-04-25T055159.564 '!$A$1:$B$35,2,0) -> 32 | D22: =VLOOKUP(B22,weeks!F$2:N69,2,0) -> 0 | E22: =VLOOKUP(B22,weeks!F$2:N69,3,0) -> 0 | F22: =VLOOKUP(B22,weeks!F$2:N69,4,0) -> 0 | G22: =VLOOKUP(B22,weeks!F$2:N69,5,0) -> 0 | H22: =VLOOKUP(B22,weeks!F$2:N69,6,0) -> 0 | I22: =VLOOKUP(B22,weeks!F$2:N69,7,0) -> 0 | J22: =VLOOKUP(B22,weeks!F$2:N69,8,0) -> 0 | K22: =SUM(D22:J22) -> 0 | L22: =K22/C22 -> 0 | N22: 0 | O22: 0 | P22: 3 | Q22: 3 | R22: 0 | S22: 0 | T22: =SUM(N22,P22,R22) -> 3
A23: 21 | B23: GUDIVADA I TOWN UPS | C23: =VLOOKUP(B23,'[1]export - 2026-04-25T055159.564 '!$A$1:$B$35,2,0) -> 31 | D23: =VLOOKUP(B23,weeks!F$2:N53,2,0) -> 0 | E23: =VLOOKUP(B23,weeks!F$2:N53,3,0) -> 0 | F23: =VLOOKUP(B23,weeks!F$2:N53,4,0) -> 0 | G23: =VLOOKUP(B23,weeks!F$2:N53,5,0) -> 0 | H23: =VLOOKUP(B23,weeks!F$2:N53,6,0) -> 0 | I23: =VLOOKUP(B23,weeks!F$2:N53,7,0) -> 0 | J23: =VLOOKUP(B23,weeks!F$2:N53,8,0) -> 0 | K23: =SUM(D23:J23) -> 0 | L23: =K23/C23 -> 0 | N23: 1 | O23: 0.076923077 | P23: 1 | Q23: 0.16666667 | R23: 0 | S23: 0 | T23: =SUM(N23,P23,R23) -> 2
A24: 22 | B24: HANUMAN JUNCTION | C24: =VLOOKUP(B24,'[1]export - 2026-04-25T055159.564 '!$A$1:$B$35,2,0) -> 32 | D24: =VLOOKUP(B24,weeks!F$2:N64,2,0) -> 0 | E24: =VLOOKUP(B24,weeks!F$2:N64,3,0) -> 0 | F24: =VLOOKUP(B24,weeks!F$2:N64,4,0) -> 0 | G24: =VLOOKUP(B24,weeks!F$2:N64,5,0) -> 1 | H24: =VLOOKUP(B24,weeks!F$2:N64,6,0) -> 0 | I24: =VLOOKUP(B24,weeks!F$2:N64,7,0) -> 0 | J24: =VLOOKUP(B24,weeks!F$2:N64,8,0) -> 0 | K24: =SUM(D24:J24) -> 1 | L24: =K24/C24 -> 0.03125 | N24: 1 | O24: 0.33333333 | P24: 0 | Q24: 0 | R24: 1 | S24: 0.03125 | T24: =SUM(N24,P24,R24) -> 2
A25: 23 | B25: PAMIDIMUKKALA | C25: =VLOOKUP(B25,'[1]export - 2026-04-25T055159.564 '!$A$1:$B$35,2,0) -> 29 | D25: =VLOOKUP(B25,weeks!F$2:N43,2,0) -> 0 | E25: =VLOOKUP(B25,weeks!F$2:N43,3,0) -> 0 | F25: =VLOOKUP(B25,weeks!F$2:N43,4,0) -> 0 | G25: =VLOOKUP(B25,weeks!F$2:N43,5,0) -> 0 | H25: =VLOOKUP(B25,weeks!F$2:N43,6,0) -> 0 | I25: =VLOOKUP(B25,weeks!F$2:N43,7,0) -> 0 | J25: =VLOOKUP(B25,weeks!F$2:N43,8,0) -> 0 | K25: =SUM(D25:J25) -> 0 | L25: =K25/C25 -> 0 | N25: 1 | O25: 0.5 | P25: 0 | Q25: 0 | R25: 0 | S25: 0 | T25: =SUM(N25,P25,R25) -> 1
A26: 24 | B26: THOTLAVALLURU | C26: =VLOOKUP(B26,'[1]export - 2026-04-25T055159.564 '!$A$1:$B$35,2,0) -> 21 | D26: =VLOOKUP(B26,weeks!F$2:N70,2,0) -> 0 | E26: =VLOOKUP(B26,weeks!F$2:N70,3,0) -> 0 | F26: =VLOOKUP(B26,weeks!F$2:N70,4,0) -> 0 | G26: =VLOOKUP(B26,weeks!F$2:N70,5,0) -> 0 | H26: =VLOOKUP(B26,weeks!F$2:N70,6,0) -> 0 | I26: =VLOOKUP(B26,weeks!F$2:N70,7,0) -> 0 | J26: =VLOOKUP(B26,weeks!F$2:N70,8,0) -> 0 | K26: =SUM(D26:J26) -> 0 | L26: =K26/C26 -> 0 | N26: 1 | O26: 0.25 | P26: 0 | Q26: 0 | R26: 0 | S26: 0 | T26: =SUM(N26,P26,R26) -> 1
A27: 25 | B27: GHANTASALA | C27: =VLOOKUP(B27,'[1]export - 2026-04-25T055159.564 '!$A$1:$B$35,2,0) -> 20 | D27: =VLOOKUP(B27,weeks!F$2:N42,2,0) -> 0 | E27: =VLOOKUP(B27,weeks!F$2:N42,3,0) -> 0 | F27: =VLOOKUP(B27,weeks!F$2:N42,4,0) -> 0 | G27: =VLOOKUP(B27,weeks!F$2:N42,5,0) -> 0 | H27: =VLOOKUP(B27,weeks!F$2:N42,6,0) -> 0 | I27: =VLOOKUP(B27,weeks!F$2:N42,7,0) -> 0 | J27: =VLOOKUP(B27,weeks!F$2:N42,8,0) -> 0 | K27: =SUM(D27:J27) -> 0 | L27: =K27/C27 -> 0 | N27: 0 | O27: 0 | P27: 0 | Q27: 0 | R27: 0 | S27: 0 | T27: =SUM(N27,P27,R27) -> 0
A28: 26 | B28: PEDANA | C28: =VLOOKUP(B28,'[1]export - 2026-04-25T055159.564 '!$A$1:$B$35,2,0) -> 25 | D28: =VLOOKUP(B28,weeks!F$2:N52,2,0) -> 0 | E28: =VLOOKUP(B28,weeks!F$2:N52,3,0) -> 0 | F28: =VLOOKUP(B28,weeks!F$2:N52,4,0) -> 0 | G28: =VLOOKUP(B28,weeks!F$2:N52,5,0) -> 0 | H28: =VLOOKUP(B28,weeks!F$2:N52,6,0) -> 0 | I28: =VLOOKUP(B28,weeks!F$2:N52,7,0) -> 0 | J28: =VLOOKUP(B28,weeks!F$2:N52,8,0) -> 0 | K28: =SUM(D28:J28) -> 0 | L28: =K28/C28 -> 0 | N28: 0 | O28: 0 | P28: 0 | Q28: 0 | R28: 0 | S28: 0 | T28: =SUM(N28,P28,R28) -> 0
A29: 27 | B29: AVANIGADDA | C29: =VLOOKUP(B29,'[1]export - 2026-04-25T055159.564 '!$A$1:$B$35,2,0) -> 17 | D29: =VLOOKUP(B29,weeks!F$2:N57,2,0) -> 0 | E29: =VLOOKUP(B29,weeks!F$2:N57,3,0) -> 0 | F29: =VLOOKUP(B29,weeks!F$2:N57,4,0) -> 0 | G29: =VLOOKUP(B29,weeks!F$2:N57,5,0) -> 0 | H29: =VLOOKUP(B29,weeks!F$2:N57,6,0) -> 0 | I29: =VLOOKUP(B29,weeks!F$2:N57,7,0) -> 0 | J29: =VLOOKUP(B29,weeks!F$2:N57,8,0) -> 0 | K29: =SUM(D29:J29) -> 0 | L29: =K29/C29 -> 0 | N29: 0 | O29: #DIV/0! | P29: 0 | Q29: 0 | R29: 0 | S29: 0 | T29: =SUM(N29,P29,R29) -> 0
A30: 28 | B30: VEERAVALLI | C30: =VLOOKUP(B30,'[1]export - 2026-04-25T055159.564 '!$A$1:$B$35,2,0) -> 13 | D30: =VLOOKUP(B30,weeks!F$2:N58,2,0) -> 0 | E30: =VLOOKUP(B30,weeks!F$2:N58,3,0) -> 0 | F30: =VLOOKUP(B30,weeks!F$2:N58,4,0) -> 0 | G30: =VLOOKUP(B30,weeks!F$2:N58,5,0) -> 0 | H30: =VLOOKUP(B30,weeks!F$2:N58,6,0) -> 0 | I30: =VLOOKUP(B30,weeks!F$2:N58,7,0) -> 0 | J30: =VLOOKUP(B30,weeks!F$2:N58,8,0) -> 0 | K30: =SUM(D30:J30) -> 0 | L30: =K30/C30 -> 0 | N30: 0 | O30: #N/A | P30: 0 | Q30: 0 | R30: 0 | S30: 0 | T30: =SUM(N30,P30,R30) -> 0
A31: 29 | B31: KRUTHIVENNU | C31: =VLOOKUP(B31,'[1]export - 2026-04-25T055159.564 '!$A$1:$B$35,2,0) -> 24 | D31: =VLOOKUP(B31,weeks!F$2:N60,2,0) -> 0 | E31: =VLOOKUP(B31,weeks!F$2:N60,3,0) -> 0 | F31: =VLOOKUP(B31,weeks!F$2:N60,4,0) -> 0 | G31: =VLOOKUP(B31,weeks!F$2:N60,5,0) -> 0 | H31: =VLOOKUP(B31,weeks!F$2:N60,6,0) -> 0 | I31: =VLOOKUP(B31,weeks!F$2:N60,7,0) -> 0 | J31: =VLOOKUP(B31,weeks!F$2:N60,8,0) -> 0 | K31: =SUM(D31:J31) -> 0 | L31: =K31/C31 -> 0 | N31: 0 | O31: 0 | P31: 0 | Q31: 0 | R31: 0 | S31: 0 | T31: =SUM(N31,P31,R31) -> 0
A32: 30 | B32: KUCHIPUDI | C32: =VLOOKUP(B32,'[1]export - 2026-04-25T055159.564 '!$A$1:$B$35,2,0) -> 6 | D32: =VLOOKUP(B32,weeks!F$2:N61,2,0) -> 0 | E32: =VLOOKUP(B32,weeks!F$2:N61,3,0) -> 0 | F32: =VLOOKUP(B32,weeks!F$2:N61,4,0) -> 0 | G32: =VLOOKUP(B32,weeks!F$2:N61,5,0) -> 0 | H32: =VLOOKUP(B32,weeks!F$2:N61,6,0) -> 0 | I32: =VLOOKUP(B32,weeks!F$2:N61,7,0) -> 0 | J32: =VLOOKUP(B32,weeks!F$2:N61,8,0) -> 0 | K32: =SUM(D32:J32) -> 0 | L32: =K32/C32 -> 0 | N32: 0 | O32: 0 | P32: 0 | Q32: 0 | R32: 0 | S32: 0 | T32: =SUM(N32,P32,R32) -> 0
A33: 31 | B33: KODURU | C33: =VLOOKUP(B33,'[1]export - 2026-04-25T055159.564 '!$A$1:$B$35,2,0) -> 17 | D33: =VLOOKUP(B33,weeks!F$2:N67,2,0) -> 0 | E33: =VLOOKUP(B33,weeks!F$2:N67,3,0) -> 0 | F33: =VLOOKUP(B33,weeks!F$2:N67,4,0) -> 0 | G33: =VLOOKUP(B33,weeks!F$2:N67,5,0) -> 0 | H33: =VLOOKUP(B33,weeks!F$2:N67,6,0) -> 0 | I33: =VLOOKUP(B33,weeks!F$2:N67,7,0) -> 0 | J33: =VLOOKUP(B33,weeks!F$2:N67,8,0) -> 0 | K33: =SUM(D33:J33) -> 0 | L33: =K33/C33 -> 0 | N33: 0 | O33: 0 | P33: 0 | Q33: #DIV/0! | R33: 0 | S33: 0 | T33: =SUM(N33,P33,R33) -> 0
A34: 32 | B34: MAHILA UPS, MACHILIPATNAM | C34: =VLOOKUP(B34,'[1]export - 2026-04-25T055159.564 '!$A$1:$B$35,2,0) -> #N/A | D34: =VLOOKUP(B34,weeks!F$2:N71,2,0) -> 0 | E34: =VLOOKUP(B34,weeks!F$2:N71,3,0) -> 0 | F34: =VLOOKUP(B34,weeks!F$2:N71,4,0) -> 0 | G34: =VLOOKUP(B34,weeks!F$2:N71,5,0) -> 0 | H34: =VLOOKUP(B34,weeks!F$2:N71,6,0) -> 0 | I34: =VLOOKUP(B34,weeks!F$2:N71,7,0) -> 0 | J34: =VLOOKUP(B34,weeks!F$2:N71,8,0) -> 0 | K34: =SUM(D34:J34) -> 0 | L34: =K34/C34 -> #N/A | N34: 0 | O34: 0 | P34: 0 | Q34: 0 | R34: 0 | S34: #N/A | T34: =SUM(N34,P34,R34) -> 0
A35: 33 | B35: GUDURU | C35: =VLOOKUP(B35,'[1]export - 2026-04-25T055159.564 '!$A$1:$B$35,2,0) -> 21 | D35: =VLOOKUP(B35,weeks!F$2:N72,2,0) -> 0 | E35: =VLOOKUP(B35,weeks!F$2:N72,3,0) -> 0 | F35: =VLOOKUP(B35,weeks!F$2:N72,4,0) -> 0 | G35: =VLOOKUP(B35,weeks!F$2:N72,5,0) -> 0 | H35: =VLOOKUP(B35,weeks!F$2:N72,6,0) -> 0 | I35: =VLOOKUP(B35,weeks!F$2:N72,7,0) -> 0 | J35: =VLOOKUP(B35,weeks!F$2:N72,8,0) -> 0 | K35: =SUM(D35:J35) -> 0 | L35: =K35/C35 -> 0 | N35: 0 | O35: 0 | P35: 0 | Q35: 0 | R35: 0 | S35: 0 | T35: =SUM(N35,P35,R35) -> 0
A36: 34 | B36: KANKIPADU | C36: =VLOOKUP(B36,'[1]export - 2026-04-25T055159.564 '!$A$1:$B$35,2,0) -> 27 | D36: =VLOOKUP(B36,weeks!F$2:N73,2,0) -> 0 | E36: =VLOOKUP(B36,weeks!F$2:N73,3,0) -> 0 | F36: =VLOOKUP(B36,weeks!F$2:N73,4,0) -> 0 | G36: =VLOOKUP(B36,weeks!F$2:N73,5,0) -> 0 | H36: =VLOOKUP(B36,weeks!F$2:N73,6,0) -> 0 | I36: =VLOOKUP(B36,weeks!F$2:N73,7,0) -> 0 | J36: =VLOOKUP(B36,weeks!F$2:N73,8,0) -> 0 | K36: =SUM(D36:J36) -> 0 | L36: =K36/C36 -> 0 | N36: 0 | O36: 0 | P36: 0 | Q36: 0 | R36: 0 | S36: 0 | T36: =SUM(N36,P36,R36) -> 0
A37: TOTAL NUMBER OF ALERTS | C37: =SUM(C3:C36) -> #N/A | D37: =SUM(D3:D36) -> 70 | E37: =SUM(E3:E36) -> 43 | F37: =SUM(F3:F36) -> 6 | G37: =SUM(G3:G36) -> 1 | H37: =SUM(H3:H36) -> 0 | I37: =SUM(I3:I36) -> 0 | J37: =SUM(J3:J36) -> 3 | K37: =SUM(K3:K36) -> 123 | L37: =K37/C37 -> #N/A | N37: =SUM(N3:N36) -> 119 | P37: =SUM(P3:P36) -> 273 | Q37: =SUM(Q3:Q36) -> #N/A | R37: =SUM(R3:R36) -> 123 | S37: =SUM(S3:S36) -> #N/A | T37: =SUM(T3:T36) -> 515

Sheet weeks
E2: 1 | F2: AVANIGADDA | G2: 0 | H2: 0 | I2: 0 | J2: 0 | K2: 0 | L2: 0 | M2: 0 | N2: 0
E3: 2 | F3: Bandar Taluk PS | G3: 0 | H3: 0 | I3: 0 | J3: 0 | K3: 0 | L3: 0 | M3: 0 | N3: 0
E4: 3 | F4: BANTUMILLI | G4: 0 | H4: 6 | I4: 0 | J4: 0 | K4: 0 | L4: 0 | M4: 0 | N4: 6
E5: 4 | F5: CHALLAPALLI | G5: 0 | H5: 0 | I5: 0 | J5: 0 | K5: 0 | L5: 0 | M5: 0 | N5: 0
E6: 5 | F6: CHILAKALAPUDI UPS | G6: 0 | H6: 0 | I6: 0 | J6: 0 | K6: 0 | L6: 0 | M6: 0 | N6: 0
E7: 6 | F7: GUDIVADA RURAL | G7: 9 | H7: 0 | I7: 4 | J7: 0 | K7: 0 | L7: 0 | M7: 1 | N7: 14
E8: 7 | F8: GUDIVADA I TOWN UPS | G8: 0 | H8: 0 | I8: 0 | J8: 0 | K8: 0 | L8: 0 | M8: 0 | N8: 0
E9: 8 | F9: GUDLAVALLERU | G9: 1 | H9: 0 | I9: 0 | J9: 0 | K9: 0 | L9: 0 | M9: 0 | N9: 1
E10: 9 | F10: GUDIVADA II TOWN UPS | G10: 31 | H10: 31 | I10: 2 | J10: 0 | K10: 0 | L10: 0 | M10: 0 | N10: 64
E11: 10 | F11: INAGUDURU UPS | G11: 3 | H11: 0 | I11: 0 | J11: 0 | K11: 0 | L11: 0 | M11: 0 | N11: 3
E12: 11 | F12: HANUMAN JUNCTION | G12: 0 | H12: 0 | I12: 0 | J12: 1 | K12: 0 | L12: 0 | M12: 0 | N12: 1
E13: 12 | F13: KUCHIPUDI | G13: 0 | H13: 0 | I13: 0 | J13: 0 | K13: 0 | L13: 0 | M13: 0 | N13: 0
... E40: 39 | F40: Gannavaram Traffic | G40: 0 | H40: 0 | I40: 0 | J40: 0 | K40: 0 | L40: 0 | M40: 0 | N40: 0
E41: TOTAL NUMBER OF ALERTS | G41: =SUM(G2:G40) -> 70 | H41: =SUM(H2:H40) -> 43 | I41: =SUM(I2:I40) -> 6 | J41: =SUM(J2:J40) -> 1 | K41: =SUM(K2:K40) -> 0 | L41: =SUM(L2:L40) -> 0 | M41: =SUM(M2:M40) -> 3 | N41: =SUM(N2:N40) -> 123

Sheet Sheet3
D1: 1 to 7
C3: 1 | D3: AVANIGADDA | E3: 0 | F3: 0 | G3: 0 | H3: 0 | I3: 0 | J3: 0 | K3: 0 | L3: 0
C4: 2 | D4: Bandar Taluk PS | E4: 0 | F4: 0 | G4: 0 | H4: 0 | I4: 0 | J4: 0 | K4: 0 | L4: 0
C5: 3 | D5: BANTUMILLI | E5: 1 | F5: 1 | G5: 0 | H5: 0 | I5: 0 | J5: 0 | K5: 0 | L5: 2
C6: 4 | D6: CHALLAPALLI | E6: 6 | F6: 8 | G6: 0 | H6: 0 | I6: 0 | J6: 0 | K6: 0 | L6: 14
C7: 5 | D7: CHILAKALAPUDI UPS | E7: 3 | F7: 15 | G7: 1 | H7: 0 | I7: 0 | J7: 0 | K7: 0 | L7: 19
C8: 6 | D8: GUDIVADA RURAL | E8: 13 | F8: 0 | G8: 0 | H8: 0 | I8: 0 | J8: 0 | K8: 0 | L8: 13
C9: 7 | D9: GUDIVADA I TOWN UPS | E9: 0 | F9: 0 | G9: 0 | H9: 0 | I9: 0 | J9: 0 | K9: 1 | L9: 1
C10: 8 | D10: GUDLAVALLERU | E10: 0 | F10: 0 | G10: 1 | H10: 0 | I10: 0 | J10: 0 | K10: 0 | L10: 1
C11: 9 | D11: GUDIVADA II TOWN UPS | E11: 6 | F11: 1 | G11: 1 | H11: 0 | I11: 0 | J11: 0 | K11: 0 | L11: 8
C12: 10 | D12: INAGUDURU UPS | E12: 1 | F12: 0 | G12: 0 | H12: 0 | I12: 0 | J12: 0 | K12: 0 | L12: 1
C13: 11 | D13: HANUMAN JUNCTION | E13: 0 | F13: 1 | G13: 0 | H13: 0 | I13: 0 | J13: 0 | K13: 0 | L13: 1
C14: 12 | D14: KUCHIPUDI | E14: 0 | F14: 0 | G14: 0 | H14: 0 | I14: 0 | J14: 0 | K14: 0 | L14: 0
... C41: 39 | D41: Gannavaram Traffic | E41: 0 | F41: 0 | G41: 0 | H41: 0 | I41: 0 | J41: 0 | K41: 0 | L41: 0
C42: TOTAL NUMBER OF ALERTS | E42: 62 | F42: 26 | G42: 7 | H42: 3 | I42: 0 | J42: 0 | K42: 21 | L42: 119

Sheet Sheet4
C2: 8 yo 14
C4: 1 | D4: AVANIGADDA | E4: 0 | F4: 0 | G4: 0 | H4: 0 | I4: 0 | J4: 0 | K4: 0 | L4: 0
C5: 2 | D5: Bandar Taluk PS | E5: 0 | F5: 9 | G5: 15 | H5: 0 | I5: 0 | J5: 0 | K5: 0 | L5: 24
C6: 3 | D6: BANTUMILLI | E6: 1 | F6: 16 | G6: 2 | H6: 0 | I6: 0 | J6: 0 | K6: 0 | L6: 19
C7: 4 | D7: CHALLAPALLI | E7: 0 | F7: 0 | G7: 0 | H7: 0 | I7: 0 | J7: 0 | K7: 0 | L7: 0
C8: 5 | D8: CHILAKALAPUDI UPS | E8: 0 | F8: 4 | G8: 2 | H8: 0 | I8: 0 | J8: 0 | K8: 0 | L8: 6
C9: 6 | D9: GUDIVADA RURAL | E9: 18 | F9: 0 | G9: 0 | H9: 0 | I9: 0 | J9: 0 | K9: 0 | L9: 18
C10: 7 | D10: GUDIVADA I TOWN UPS | E10: 0 | F10: 0 | G10: 0 | H10: 0 | I10: 0 | J10: 0 | K10: 1 | L10: 1
C11: 8 | D11: GUDLAVALLERU | E11: 0 | F11: 0 | G11: 1 | H11: 0 | I11: 0 | J11: 0 | K11: 0 | L11: 1
C12: 9 | D12: GUDIVADA II TOWN UPS | E12: 82 | F12: 11 | G12: 3 | H12: 0 | I12: 0 | J12: 0 | K12: 0 | L12: 96
C13: 10 | D13: INAGUDURU UPS | E13: 5 | F13: 0 | G13: 0 | H13: 0 | I13: 0 | J13: 0 | K13: 0 | L13: 5
C14: 11 | D14: HANUMAN JUNCTION | E14: 0 | F14: 0 | G14: 0 | H14: 0 | I14: 0 | J14: 0 | K14: 0 | L14: 0
C15: 12 | D15: KUCHIPUDI | E15: 0 | F15: 0 | G15: 0 | H15: 0 | I15: 0 | J15: 0 | K15: 0 | L15: 0
... C42: 39 | D42: Gannavaram Traffic | E42: 0 | F42: 0 | G42: 0 | H42: 0 | I42: 0 | J42: 0 | K42: 0 | L42: 0
C43: TOTAL NUMBER OF ALERTS | E43: 154 | F43: 68 | G43: 24 | H43: 0 | I43: 0 | J43: 0 | K43: 27 | L43: 273

Sheet Sheet5
C2: 15 to 21
C4: 1 | D4: AVANIGADDA | E4: 0 | F4: 0 | G4: 0 | H4: 0 | I4: 0 | J4: 0 | K4: 0 | L4: 0
C5: 2 | D5: Bandar Taluk PS | E5: 0 | F5: 0 | G5: 0 | H5: 0 | I5: 0 | J5: 0 | K5: 0 | L5: 0
C6: 3 | D6: BANTUMILLI | E6: 0 | F6: 6 | G6: 0 | H6: 0 | I6: 0 | J6: 0 | K6: 0 | L6: 6
C7: 4 | D7: CHALLAPALLI | E7: 0 | F7: 0 | G7: 0 | H7: 0 | I7: 0 | J7: 0 | K7: 0 | L7: 0
C8: 5 | D8: CHILAKALAPUDI UPS | E8: 0 | F8: 0 | G8: 0 | H8: 0 | I8: 0 | J8: 0 | K8: 0 | L8: 0
C9: 6 | D9: GUDIVADA RURAL | E9: 9 | F9: 0 | G9: 4 | H9: 0 | I9: 0 | J9: 0 | K9: 1 | L9: 14
C10: 7 | D10: GUDIVADA I TOWN UPS | E10: 0 | F10: 0 | G10: 0 | H10: 0 | I10: 0 | J10: 0 | K10: 0 | L10: 0
C11: 8 | D11: GUDLAVALLERU | E11: 1 | F11: 0 | G11: 0 | H11: 0 | I11: 0 | J11: 0 | K11: 0 | L11: 1
C12: 9 | D12: GUDIVADA II TOWN UPS | E12: 31 | F12: 31 | G12: 2 | H12: 0 | I12: 0 | J12: 0 | K12: 0 | L12: 64
C13: 10 | D13: INAGUDURU UPS | E13: 3 | F13: 0 | G13: 0 | H13: 0 | I13: 0 | J13: 0 | K13: 0 | L13: 3
C14: 11 | D14: HANUMAN JUNCTION | E14: 0 | F14: 0 | G14: 0 | H14: 1 | I14: 0 | J14: 0 | K14: 0 | L14: 1
C15: 12 | D15: KUCHIPUDI | E15: 0 | F15: 0 | G15: 0 | H15: 0 | I15: 0 | J15: 0 | K15: 0 | L15: 0
... C42: 39 | D42: Gannavaram Traffic | E42: 0 | F42: 0 | G42: 0 | H42: 0 | I42: 0 | J42: 0 | K42: 0 | L42: 0
C43: TOTAL NUMBER OF ALERTS | E43: 70 | F43: 43 | G43: 6 | H43: 1 | I43: 0 | J43: 0 | K43: 3 | L43: 123
