Workbook

Sheet 1_MEDLEAPR_PME
A1: MEDLEAPR PME CASES REQUIRED VS GENERATED BETWEEN 09-09-2026 TO 15-09-2026 - (2.5% Marks)
A2: S.NO | B2: PS NAME | C2: Total Cases Reported | D2: No. of Cases required PME | E2: No. of Cases Requests Raised | F2: % Requests Completed | G2: Raw Value | H2: Marks
A3: 1 | B3: A.Koduru | C3: 0 | D3: 0 | E3: 0 | F3: =IF(AND(D3=0),"100.00",IF(AND(E3*100/D3>100),"100.00",(E3*100/D3))) -> 100.00 | G3: =F3 -> 100.00 | H3: =G3*2.5% -> 2.5
A4: 2 | B4: Anakapalli Rural | C4: 3 | D4: 3 | E4: 3 | F4: =IF(AND(D4=0),"100.00",IF(AND(E4*100/D4>100),"100.00",(E4*100/D4))) -> 100 | G4: =F4 -> 100 | H4: =G4*2.5% -> 2.5
A5: 3 | B5: Anakapalli Town | C5: 0 | D5: 0 | E5: 0 | F5: =IF(AND(D5=0),"100.00",IF(AND(E5*100/D5>100),"100.00",(E5*100/D5))) -> 100.00 | G5: =F5 -> 100.00 | H5: =G5*2.5% -> 2.5
A6: 4 | B6: Anakapalli Traffic | C6: 0 | D6: 0 | E6: 0 | F6: =IF(AND(D6=0),"100.00",IF(AND(E6*100/D6>100),"100.00",(E6*100/D6))) -> 100.00 | G6: =F6 -> 100.00 | H6: =G6*2.5% -> 2.5
A7: 5 | B7: Atchutapuram | C7: 3 | D7: 3 | E7: 3 | F7: =IF(AND(D7=0),"100.00",IF(AND(E7*100/D7>100),"100.00",(E7*100/D7))) -> 100 | G7: =F7 -> 100 | H7: =G7*2.5% -> 2.5
A8: 6 | B8: Butchiyyapeta | C8: 3 | D8: 3 | E8: 3 | F8: =IF(AND(D8=0),"100.00",IF(AND(E8*100/D8>100),"100.00",(E8*100/D8))) -> 100 | G8: =F8 -> 100 | H8: =G8*2.5% -> 2.5
A9: 7 | B9: Cheedikada | C9: 0 | D9: 0 | E9: 0 | F9: =IF(AND(D9=0),"100.00",IF(AND(E9*100/D9>100),"100.00",(E9*100/D9))) -> 100.00 | G9: =F9 -> 100.00 | H9: =G9*2.5% -> 2.5
A10: 8 | B10: Chodavaram | C10: 0 | D10: 0 | E10: 0 | F10: =IF(AND(D10=0),"100.00",IF(AND(E10*100/D10>100),"100.00",(E10*100/D10))) -> 100.00 | G10: =F10 -> 100.00 | H10: =G10*2.5% -> 2.5
A11: 9 | B11: Devarapalli | C11: 0 | D11: 0 | E11: 0 | F11: =IF(AND(D11=0),"100.00",IF(AND(E11*100/D11>100),"100.00",(E11*100/D11))) -> 100.00 | G11: =F11 -> 100.00 | H11: =G11*2.5% -> 2.5
A12: 10 | B12: Golugonda | C12: 0 | D12: 0 | E12: 0 | F12: =IF(AND(D12=0),"100.00",IF(AND(E12*100/D12>100),"100.00",(E12*100/D12))) -> 100.00 | G12: =F12 -> 100.00 | H12: =G12*2.5% -> 2.5
A13: 11 | B13: K.D.Peta | C13: 0 | D13: 0 | E13: 0 | F13: =IF(AND(D13=0),"100.00",IF(AND(E13*100/D13>100),"100.00",(E13*100/D13))) -> 100.00 | G13: =F13 -> 100.00 | H13: =G13*2.5% -> 2.5
A14: 12 | B14: K.Kotapadu | C14: 0 | D14: 0 | E14: 0 | F14: =IF(AND(D14=0),"100.00",IF(AND(E14*100/D14>100),"100.00",(E14*100/D14))) -> 100.00 | G14: =F14 -> 100.00 | H14: =G14*2.5% -> 2.5
... A35: 33 | B35: Yelamanchili Traffic | C35: 0 | D35: 0 | E35: 0 | F35: =IF(AND(D35=0),"100.00",IF(AND(E35*100/D35>100),"100.00",(E35*100/D35))) -> 100.00 | G35: =F35 -> 100.00 | H35: =G35*2.5% -> 2.5
A36: GRAND TOTAL | C36: =SUM(C3:C35) -> 19 | D36: =SUM(D3:D35) -> 19 | E36: =SUM(E3:E35) -> 19 | F36: =AVERAGE(F3:F35) -> 100 | G36: =AVERAGE(G3:G35) -> 100 | H36: =AVERAGE(H3:H35) -> 2.5

Sheet 2_MEDLEAPR_MLC
A1: MEDLEAPR MLC CASES REQUIRED VS GENERATED BETWEEN 09-09-2026 TO 15-09-2026 - (2.5% Marks)
A2: S.NO | B2: PS NAME | C2: Total Cases Reported | D2: No. of Cases required MLC | E2: No. of Cases Requests Raised | F2: % Requests | G2: Raw Value | H2: Marks
A3: 1 | B3: A.Koduru | C3: 0 | D3: 0 | E3: 0 | F3: =IF(AND(D3=0),"100.00",IF(AND(E3*100/D3>100),"100.00",(E3*100/D3))) -> 100.00 | G3: =F3 -> 100.00 | H3: =G3*2.5% -> 2.5
A4: 2 | B4: Anakapalli Rural | C4: 1 | D4: 1 | E4: 1 | F4: =IF(AND(D4=0),"100.00",IF(AND(E4*100/D4>100),"100.00",(E4*100/D4))) -> 100 | G4: =F4 -> 100 | H4: =G4*2.5% -> 2.5
A5: 3 | B5: Anakapalli Town | C5: 0 | D5: 0 | E5: 0 | F5: =IF(AND(D5=0),"100.00",IF(AND(E5*100/D5>100),"100.00",(E5*100/D5))) -> 100.00 | G5: =F5 -> 100.00 | H5: =G5*2.5% -> 2.5
A6: 4 | B6: Anakapalli Traffic | C6: 1 | D6: 1 | E6: 1 | F6: =IF(AND(D6=0),"100.00",IF(AND(E6*100/D6>100),"100.00",(E6*100/D6))) -> 100 | G6: =F6 -> 100 | H6: =G6*2.5% -> 2.5
A7: 5 | B7: Atchutapuram | C7: 1 | D7: 1 | E7: 1 | F7: =IF(AND(D7=0),"100.00",IF(AND(E7*100/D7>100),"100.00",(E7*100/D7))) -> 100 | G7: =F7 -> 100 | H7: =G7*2.5% -> 2.5
A8: 6 | B8: Butchiyyapeta | C8: 0 | D8: 0 | E8: 0 | F8: =IF(AND(D8=0),"100.00",IF(AND(E8*100/D8>100),"100.00",(E8*100/D8))) -> 100.00 | G8: =F8 -> 100.00 | H8: =G8*2.5% -> 2.5
A9: 7 | B9: Cheedikada | C9: 0 | D9: 0 | E9: 0 | F9: =IF(AND(D9=0),"100.00",IF(AND(E9*100/D9>100),"100.00",(E9*100/D9))) -> 100.00 | G9: =F9 -> 100.00 | H9: =G9*2.5% -> 2.5
A10: 8 | B10: Chodavaram | C10: 0 | D10: 0 | E10: 0 | F10: =IF(AND(D10=0),"100.00",IF(AND(E10*100/D10>100),"100.00",(E10*100/D10))) -> 100.00 | G10: =F10 -> 100.00 | H10: =G10*2.5% -> 2.5
A11: 9 | B11: Devarapalli | C11: 0 | D11: 0 | E11: 0 | F11: =IF(AND(D11=0),"100.00",IF(AND(E11*100/D11>100),"100.00",(E11*100/D11))) -> 100.00 | G11: =F11 -> 100.00 | H11: =G11*2.5% -> 2.5
A12: 10 | B12: Golugonda | C12: 0 | D12: 0 | E12: 0 | F12: =IF(AND(D12=0),"100.00",IF(AND(E12*100/D12>100),"100.00",(E12*100/D12))) -> 100.00 | G12: =F12 -> 100.00 | H12: =G12*2.5% -> 2.5
A13: 11 | B13: K.D.Peta | C13: 0 | D13: 0 | E13: 0 | F13: =IF(AND(D13=0),"100.00",IF(AND(E13*100/D13>100),"100.00",(E13*100/D13))) -> 100.00 | G13: =F13 -> 100.00 | H13: =G13*2.5% -> 2.5
A14: 12 | B14: K.Kotapadu | C14: 0 | D14: 0 | E14: 0 | F14: =IF(AND(D14=0),"100.00",IF(AND(E14*100/D14>100),"100.00",(E14*100/D14))) -> 100.00 | G14: =F14 -> 100.00 | H14: =G14*2.5% -> 2.5
... A35: 33 | B35: Yelamanchili Traffic | C35: 0 | D35: 0 | E35: 0 | F35: =IF(AND(D35=0),"100.00",IF(AND(E35*100/D35>100),"100.00",(E35*100/D35))) -> 100.00 | G35: =F35 -> 100.00 | H35: =G35*2.5% -> 2.5
A36: GRAND TOTAL | C36: =SUM(C3:C35) -> 14 | D36: =SUM(D3:D35) -> 14 | E36: =SUM(E3:E35) -> 14 | F36: =AVERAGE(F3:F35) -> 100 | G36: =AVERAGE(G3:G35) -> 100 | H36: =AVERAGE(H3:H35) -> 2.5

Sheet 3_NATGRID
A1: NAT GRID - (Not applicable to police Station) GENERATED BETWEEN 09-09-2026 TO 15-09-2026 - (5% Marks)
A2: S.No | B2: PS NAME | C2: Total Gandiva searches | D2: Total Sudarshan searches | E2: Gandiva Raw Value | F2: Sudharshan Raw Value | G2: NATGRID Raw Value | H2: Marks
A3: 1 | B3: A.Koduru | C3: NA | D3: NA | E3: 0 | F3: 0 | G3: =(E3+F3)/2 -> 0 | H3: =G3*5% -> 0
A4: 2 | B4: Anakapalli Rural | C4: NA | D4: NA | E4: 0 | F4: 0 | G4: =(E4+F4)/2 -> 0 | H4: =G4*5% -> 0
A5: 3 | B5: Anakapalli Town | C5: NA | D5: NA | E5: 0 | F5: 0 | G5: =(E5+F5)/2 -> 0 | H5: =G5*5% -> 0
A6: 4 | B6: Anakapalli Traffic | C6: NA | D6: NA | E6: 0 | F6: 0 | G6: =(E6+F6)/2 -> 0 | H6: =G6*5% -> 0
A7: 5 | B7: Atchutapuram | C7: NA | D7: NA | E7: 0 | F7: 0 | G7: =(E7+F7)/2 -> 0 | H7: =G7*5% -> 0
A8: 6 | B8: Butchiyyapeta | C8: NA | D8: NA | E8: 0 | F8: 0 | G8: =(E8+F8)/2 -> 0 | H8: =G8*5% -> 0
A9: 7 | B9: Cheedikada | C9: NA | D9: NA | E9: 0 | F9: 0 | G9: =(E9+F9)/2 -> 0 | H9: =G9*5% -> 0
A10: 8 | B10: Chodavaram | C10: NA | D10: NA | E10: 0 | F10: 0 | G10: =(E10+F10)/2 -> 0 | H10: =G10*5% -> 0
A11: 9 | B11: Devarapalli | C11: NA | D11: NA | E11: 0 | F11: 0 | G11: =(E11+F11)/2 -> 0 | H11: =G11*5% -> 0
A12: 10 | B12: Golugonda | C12: NA | D12: NA | E12: 0 | F12: 0 | G12: =(E12+F12)/2 -> 0 | H12: =G12*5% -> 0
A13: 11 | B13: K.D.Peta | C13: NA | D13: NA | E13: 0 | F13: 0 | G13: =(E13+F13)/2 -> 0 | H13: =G13*5% -> 0
A14: 12 | B14: K.Kotapadu | C14: NA | D14: NA | E14: 0 | F14: 0 | G14: =(E14+F14)/2 -> 0 | H14: =G14*5% -> 0
... A35: 33 | B35: Yelamanchili Traffic | C35: NA | D35: NA | E35: 0 | F35: 0 | G35: =(E35+F35)/2 -> 0 | H35: =G35*5% -> 0
A36: Total | C36: 0 | D36: 0 | E36: 0 | F36: 0 | G36: 0

Sheet 4_DGP_DASH
A1: DGP DASH BOARD ENTRIES PS WISE - ENTRIES MADE ON LAST SUNDAY (13-09-2026) (2.5% Marks)
A2: S.No | B2: Police Station | C2: SHO Remarks | D2: RAW Value | E2: Marks
A3: 1 | B3: A.Koduru | C3: Submitted | D3: 100 | E3: =D3*2.5% -> 2.5
A4: 2 | B4: Anakapalli Rural | C4: Submitted | D4: 100 | E4: =D4*2.5% -> 2.5
A5: 3 | B5: Anakapalli Town | C5: Submitted | D5: 100 | E5: =D5*2.5% -> 2.5
A6: 4 | B6: Anakapalli Traffic | C6: Submitted | D6: 100 | E6: =D6*2.5% -> 2.5
A7: 5 | B7: Atchutapuram | C7: Submitted | D7: 100 | E7: =D7*2.5% -> 2.5
A8: 6 | B8: Butchiyyapeta | C8: Submitted | D8: 100 | E8: =D8*2.5% -> 2.5
A9: 7 | B9: Cheedikada | C9: Submitted | D9: 100 | E9: =D9*2.5% -> 2.5
A10: 8 | B10: Chodavaram | C10: Submitted | D10: 100 | E10: =D10*2.5% -> 2.5
A11: 9 | B11: Devarapalli | C11: Submitted | D11: 100 | E11: =D11*2.5% -> 2.5
A12: 10 | B12: Golugonda | C12: Submitted | D12: 100 | E12: =D12*2.5% -> 2.5
A13: 11 | B13: K.D.Peta | C13: Submitted | D13: 100 | E13: =D13*2.5% -> 2.5
A14: 12 | B14: K.Kotapadu | C14: Submitted | D14: 100 | E14: =D14*2.5% -> 2.5
... A35: 33 | B35: Yelamanchili Traffic | C35: Submitted | D35: 100 | E35: =D35*2.5% -> 2.5
A36: GRAND TOTAL | D36: 100

Sheet 5_CCTNS_TILL
A1: PS wise CCTNS Application Usage Statistics From 01-01-2016 to 15-09-2026 - (2.5% Marks)
A2: S.No | B2: PS | C2: FIR | D2: CDF | E2: ACS | F2: PSS | G2: CD PartI | H2: CD Part II | I2: Charge Sheet | J2: Final Report | K2: Court Disposal | L2: 41 Crpc | M2: Forms per FIR | N2: Raw Value | O2: MARKS
A3: 1 | B3: A.Koduru | C3: 1607 | D3: 1732 | E3: 542 | F3: 98 | G3: 11171 | H3: 6742 | I3: 1373 | J3: 496 | K3: 574 | L3: 1613 | M3: =SUM(D3:L3)/C3 -> 15.146857 | N3: =ROUND(IF(M3>=$M$36,100,(M3/$M$36)*100),2) -> 100 | O3: =N3*2.5% -> 2.5
A4: 2 | B4: Anakapalli Rural | C4: 3631 | D4: 3242 | E4: 1398 | F4: 391 | G4: 12263 | H4: 16941 | I4: 3500 | J4: 1449 | K4: 2599 | L4: 4247 | M4: =SUM(D4:L4)/C4 -> 12.676948 | N4: =ROUND(IF(M4>=$M$36,100,(M4/$M$36)*100),2) -> 96.48 | O4: =N4*2.5% -> 2.412
A5: 3 | B5: Anakapalli Town | C5: 6259 | D5: 3940 | E5: 2217 | F5: 439 | G5: 20753 | H5: 21246 | I5: 5401 | J5: 3310 | K5: 3288 | L5: 5810 | M5: =SUM(D5:L5)/C5 -> 10.609363 | N5: =ROUND(IF(M5>=$M$36,100,(M5/$M$36)*100),2) -> 80.74 | O5: =N5*2.5% -> 2.0185
A6: 4 | B6: Anakapalli Traffic | C6: 1008 | D6: 1037 | E6: 519 | F6: 0 | G6: 3882 | H6: 5804 | I6: 1328 | J6: 162 | K6: 988 | L6: 909 | M6: =SUM(D6:L6)/C6 -> 14.512897 | N6: =ROUND(IF(M6>=$M$36,100,(M6/$M$36)*100),2) -> 100 | O6: =N6*2.5% -> 2.5
A7: 5 | B7: Atchutapuram | C7: 3339 | D7: 3238 | E7: 1019 | F7: 674 | G7: 12033 | H7: 14882 | I7: 2879 | J7: 1448 | K7: 1439 | L7: 4552 | M7: =SUM(D7:L7)/C7 -> 12.627733 | N7: =ROUND(IF(M7>=$M$36,100,(M7/$M$36)*100),2) -> 96.1 | O7: =N7*2.5% -> 2.4025
A8: 6 | B8: Butchiyyapeta | C8: 2522 | D8: 1891 | E8: 1194 | F8: 109 | G8: 8497 | H8: 11360 | I8: 2220 | J8: 804 | K8: 945 | L8: 2753 | M8: =SUM(D8:L8)/C8 -> 11.805313 | N8: =ROUND(IF(M8>=$M$36,100,(M8/$M$36)*100),2) -> 89.84 | O8: =N8*2.5% -> 2.246
A9: 7 | B9: Cheedikada | C9: 1709 | D9: 1786 | E9: 781 | F9: 702 | G9: 13590 | H9: 6894 | I9: 1413 | J9: 548 | K9: 624 | L9: 1443 | M9: =SUM(D9:L9)/C9 -> 16.255705 | N9: =ROUND(IF(M9>=$M$36,100,(M9/$M$36)*100),2) -> 100 | O9: =N9*2.5% -> 2.5
A10: 8 | B10: Chodavaram | C10: 4696 | D10: 3193 | E10: 2439 | F10: 258 | G10: 18802 | H10: 20962 | I10: 4028 | J10: 1520 | K10: 1838 | L10: 5208 | M10: =SUM(D10:L10)/C10 -> 12.403748 | N10: =ROUND(IF(M10>=$M$36,100,(M10/$M$36)*100),2) -> 94.4 | O10: =N10*2.5% -> 2.36
A11: 9 | B11: Devarapalli | C11: 2760 | D11: 2900 | E11: 920 | F11: 76 | G11: 9449 | H11: 11056 | I11: 2282 | J11: 855 | K11: 852 | L11: 3590 | M11: =SUM(D11:L11)/C11 -> 11.586957 | N11: =ROUND(IF(M11>=$M$36,100,(M11/$M$36)*100),2) -> 88.18 | O11: =N11*2.5% -> 2.2045
A12: 10 | B12: Golugonda | C12: 1607 | D12: 1844 | E12: 1294 | F12: 44 | G12: 9746 | H12: 7691 | I12: 1641 | J12: 707 | K12: 676 | L12: 1913 | M12: =SUM(D12:L12)/C12 -> 15.902925 | N12: =ROUND(IF(M12>=$M$36,100,(M12/$M$36)*100),2) -> 100 | O12: =N12*2.5% -> 2.5
A13: 11 | B13: K.D.Peta | C13: 1041 | D13: 1037 | E13: 792 | F13: 117 | G13: 3017 | H13: 4808 | I13: 941 | J13: 354 | K13: 261 | L13: 893 | M13: =SUM(D13:L13)/C13 -> 11.738713 | N13: =ROUND(IF(M13>=$M$36,100,(M13/$M$36)*100),2) -> 89.34 | O13: =N13*2.5% -> 2.2335
A14: 12 | B14: K.Kotapadu | C14: 1775 | D14: 1815 | E14: 544 | F14: 99 | G14: 7318 | H14: 8905 | I14: 1548 | J14: 550 | K14: 656 | L14: 2118 | M14: =SUM(D14:L14)/C14 -> 13.269296 | N14: =ROUND(IF(M14>=$M$36,100,(M14/$M$36)*100),2) -> 100 | O14: =N14*2.5% -> 2.5
... A35: 33 | B35: Yelamanchili Traffic | C35: 45 | D35: 45 | E35: 0 | F35: 0 | G35: 193 | H35: 141 | I35: 42 | J35: 0 | K35: 17 | L35: 45 | M35: =SUM(D35:L35)/C35 -> 10.733333 | N35: =ROUND(IF(M35>=$M$36,100,(M35/$M$36)*100),2) -> 81.69 | O35: =N35*2.5% -> 2.04225
A36: GRAND TOTAL | C36: =SUM(C3:C35) -> 85748 | D36: =SUM(D3:D35) -> 75562 | E36: =SUM(E3:E35) -> 34687 | F36: =SUM(F3:F35) -> 8857 | G36: =SUM(G3:G35) -> 367566 | H36: =SUM(H3:H35) -> 365095 | I36: =SUM(I3:I35) -> 77391 | J36: =SUM(J3:J35) -> 33164 | ... L36: =SUM(L3:L35) -> 97443 | M36: =AVERAGE(M3:M35) -> 13.139786 | N36: =AVERAGE(N3:N35) -> 94.550303 | O36: =AVERAGE(O3:O35) -> 2.3637576

Sheet 6_CCTNS_1_7
A1: WEEK CCTNS Application Usage Statistics (Forms 1-7) From 09-09-2026 TO 15-09-2026 - (2.5 % Marks)
A2: S.No | B2: PS | C2: FIR | D2: CDF | E2: ACS | F2: PSS | G2: CD PartI | H2: CD Part II | I2: Charge Sheet | J2: Final Report | K2: Court Disposal | L2: 41 Crpc | M2: Forms per FIR | N2: Raw Value | O2: MARKS
A3: 1 | B3: A.Koduru | C3: 0 | D3: 0 | E3: 0 | F3: 0 | G3: 0 | H3: 0 | I3: 0 | J3: 0 | K3: 0 | L3: 0 | M3: =IFERROR(SUM(D3:L3)/C3,0) -> 0 | N3: =IF(C3=0,50,ROUND(IF(M3>=$M$36,100,(M3/$M$36)*100),2)) -> 50 | O3: =N3*2.5% -> 1.25
A4: 2 | B4: Anakapalli Rural | C4: 3 | D4: 1 | E4: 0 | F4: 1 | G4: 1 | H4: 25 | I4: 0 | J4: 0 | K4: 0 | L4: 1 | M4: =IFERROR(SUM(D4:L4)/C4,0) -> 9.6666667 | N4: =IF(C4=0,50,ROUND(IF(M4>=$M$36,100,(M4/$M$36)*100),2)) -> 100 | O4: =N4*2.5% -> 2.5
A5: 3 | B5: Anakapalli Town | C5: 1 | D5: 1 | E5: 0 | F5: 0 | G5: 1 | H5: 5 | I5: 0 | J5: 0 | K5: 0 | L5: 0 | M5: =IFERROR(SUM(D5:L5)/C5,0) -> 7 | N5: =IF(C5=0,50,ROUND(IF(M5>=$M$36,100,(M5/$M$36)*100),2)) -> 100 | O5: =N5*2.5% -> 2.5
A6: 4 | B6: Anakapalli Traffic | C6: 4 | D6: 3 | E6: 0 | F6: 0 | G6: 6 | H6: 9 | I6: 3 | J6: 0 | K6: 1 | L6: 4 | M6: =IFERROR(SUM(D6:L6)/C6,0) -> 6.5 | N6: =IF(C6=0,50,ROUND(IF(M6>=$M$36,100,(M6/$M$36)*100),2)) -> 96.7 | O6: =N6*2.5% -> 2.4175
A7: 5 | B7: Atchutapuram | C7: 9 | D7: 9 | E7: 0 | F7: 1 | G7: 39 | H7: 39 | I7: 0 | J7: 0 | K7: 0 | L7: 0 | M7: =IFERROR(SUM(D7:L7)/C7,0) -> 9.7777778 | N7: =IF(C7=0,50,ROUND(IF(M7>=$M$36,100,(M7/$M$36)*100),2)) -> 100 | O7: =N7*2.5% -> 2.5
A8: 6 | B8: Butchiyyapeta | C8: 2 | D8: 1 | E8: 0 | F8: 1 | G8: 1 | H8: 6 | I8: 0 | J8: 0 | K8: 0 | L8: 5 | M8: =IFERROR(SUM(D8:L8)/C8,0) -> 7 | N8: =IF(C8=0,50,ROUND(IF(M8>=$M$36,100,(M8/$M$36)*100),2)) -> 100 | O8: =N8*2.5% -> 2.5
A9: 7 | B9: Cheedikada | C9: 2 | D9: 2 | E9: 0 | F9: 0 | G9: 5 | H9: 9 | I9: 0 | J9: 0 | K9: 0 | L9: 1 | M9: =IFERROR(SUM(D9:L9)/C9,0) -> 8.5 | N9: =IF(C9=0,50,ROUND(IF(M9>=$M$36,100,(M9/$M$36)*100),2)) -> 100 | O9: =N9*2.5% -> 2.5
A10: 8 | B10: Chodavaram | C10: 2 | D10: 2 | E10: 0 | F10: 0 | G10: 4 | H10: 3 | I10: 0 | J10: 0 | K10: 0 | L10: 1 | M10: =IFERROR(SUM(D10:L10)/C10,0) -> 5 | N10: =IF(C10=0,50,ROUND(IF(M10>=$M$36,100,(M10/$M$36)*100),2)) -> 74.39 | O10: =N10*2.5% -> 1.85975
A11: 9 | B11: Devarapalli | C11: 0 | D11: 0 | E11: 0 | F11: 0 | G11: 0 | H11: 0 | I11: 0 | J11: 0 | K11: 0 | L11: 0 | M11: =IFERROR(SUM(D11:L11)/C11,0) -> 0 | N11: =IF(C11=0,50,ROUND(IF(M11>=$M$36,100,(M11/$M$36)*100),2)) -> 50 | O11: =N11*2.5% -> 1.25
A12: 10 | B12: Golugonda | C12: 2 | D12: 2 | E12: 0 | F12: 0 | G12: 1 | H12: 8 | I12: 0 | J12: 0 | K12: 0 | L12: 0 | M12: =IFERROR(SUM(D12:L12)/C12,0) -> 5.5 | N12: =IF(C12=0,50,ROUND(IF(M12>=$M$36,100,(M12/$M$36)*100),2)) -> 81.83 | O12: =N12*2.5% -> 2.04575
A13: 11 | B13: K.D.Peta | C13: 1 | D13: 1 | E13: 0 | F13: 0 | G13: 1 | H13: 5 | I13: 0 | J13: 0 | K13: 0 | L13: 5 | M13: =IFERROR(SUM(D13:L13)/C13,0) -> 12 | N13: =IF(C13=0,50,ROUND(IF(M13>=$M$36,100,(M13/$M$36)*100),2)) -> 100 | O13: =N13*2.5% -> 2.5
A14: 12 | B14: K.Kotapadu | C14: 3 | D14: 2 | E14: 0 | F14: 0 | G14: 0 | H14: 9 | I14: 0 | J14: 0 | K14: 0 | L14: 0 | M14: =IFERROR(SUM(D14:L14)/C14,0) -> 3.6666667 | N14: =IF(C14=0,50,ROUND(IF(M14>=$M$36,100,(M14/$M$36)*100),2)) -> 54.55 | O14: =N14*2.5% -> 1.36375
... A35: 33 | B35: Yelamanchili Traffic | C35: 2 | D35: 2 | E35: 0 | F35: 0 | G35: 6 | H35: 6 | I35: 0 | J35: 0 | K35: 0 | L35: 2 | M35: =IFERROR(SUM(D35:L35)/C35,0) -> 8 | N35: =IF(C35=0,50,ROUND(IF(M35>=$M$36,100,(M35/$M$36)*100),2)) -> 100 | O35: =N35*2.5% -> 2.5
A36: GRAND TOTAL | C36: 79 | D36: 67 | E36: 3 | F36: 7 | G36: 209 | H36: 209 | I36: 3 | J36: 0 | K36: 2 | L36: 31 | M36: =IFERROR(SUM(D36:L36)/C36,0) -> 6.721519 | N36: =AVERAGE(N3:N35) -> 80.408788 | O36: =N36*2.5% -> 2.0102197

Sheet 7_CCTNS_8_15
A1: WEEK CCTNS Application Usage Statistics (Forms 8-15) From 09-09-2026 TO 15-09-2026 - (2.5 % Marks)
A2: S.No | B2: PS | C2: Result of Appeal | D2: Missing | E2: Abandoned Person entry | F2: Unidentified Dead Body | G2: Unnatural Death | H2: Gang Profile | I2: Member Details | J2: Gang Activity Details | K2: Unclaimed Property | L2: Raw Value | M2: Marks
A3: 1 | B3: A.Koduru | C3: NA | D3: NA | E3: NA | F3: NA | G3: NA | H3: NA | I3: NA | J3: NA | K3: NA | L3: 0 | M3: =L3*2.5% -> 0
A4: 2 | B4: Anakapalli Rural | C4: NA | D4: NA | E4: NA | F4: NA | G4: NA | H4: NA | I4: NA | J4: NA | K4: NA | L4: 0 | M4: =L4*2.5% -> 0
A5: 3 | B5: Anakapalli Town | C5: NA | D5: NA | E5: NA | F5: NA | G5: NA | H5: NA | I5: NA | J5: NA | K5: NA | L5: 0 | M5: =L5*2.5% -> 0
A6: 4 | B6: Anakapalli Traffic | C6: NA | D6: NA | E6: NA | F6: NA | G6: NA | H6: NA | I6: NA | J6: NA | K6: NA | L6: 0 | M6: =L6*2.5% -> 0
A7: 5 | B7: Atchutapuram | C7: NA | D7: NA | E7: NA | F7: NA | G7: NA | H7: NA | I7: NA | J7: NA | K7: NA | L7: 0 | M7: =L7*2.5% -> 0
A8: 6 | B8: Butchiyyapeta | C8: NA | D8: NA | E8: NA | F8: NA | G8: NA | H8: NA | I8: NA | J8: NA | K8: NA | L8: 0 | M8: =L8*2.5% -> 0
A9: 7 | B9: Cheedikada | C9: NA | D9: NA | E9: NA | F9: NA | G9: NA | H9: NA | I9: NA | J9: NA | K9: NA | L9: 0 | M9: =L9*2.5% -> 0
A10: 8 | B10: Chodavaram | C10: NA | D10: NA | E10: NA | F10: NA | G10: NA | H10: NA | I10: NA | J10: NA | K10: NA | L10: 0 | M10: =L10*2.5% -> 0
A11: 9 | B11: Devarapalli | C11: NA | D11: NA | E11: NA | F11: NA | G11: NA | H11: NA | I11: NA | J11: NA | K11: NA | L11: 0 | M11: =L11*2.5% -> 0
A12: 10 | B12: Golugonda | C12: NA | D12: NA | E12: NA | F12: NA | G12: NA | H12: NA | I12: NA | J12: NA | K12: NA | L12: 0 | M12: =L12*2.5% -> 0
A13: 11 | B13: K.D.Peta | C13: NA | D13: NA | E13: NA | F13: NA | G13: NA | H13: NA | I13: NA | J13: NA | K13: NA | L13: 0 | M13: =L13*2.5% -> 0
A14: 12 | B14: K.Kotapadu | C14: NA | D14: NA | E14: NA | F14: NA | G14: NA | H14: NA | I14: NA | J14: NA | K14: NA | L14: 0 | M14: =L14*2.5% -> 0
... A35: 33 | B35: Yelamanchili Traffic | C35: NA | D35: NA | E35: NA | F35: NA | G35: NA | H35: NA | I35: NA | J35: NA | K35: NA | L35: 0 | M35: =L35*2.5% -> 0
A36: GRAND TOTAL | C36: NA | D36: NA | E36: NA | F36: NA | G36: NA | H36: NA | I36: NA | J36: NA | K36: NA | L36: 0 | M36: =L36*2.5% -> 0

Sheet 8_ZERO_FIRS
A1: STATUS OF ZERO FIRs GENERATED BETWEEN 09-09-2026 TO 15-09-2026 - (5% Marks)
A2: S.NO | B2: PS Name | C2: No. of Zero FIRs Registered | D2: Pending to Transfer | E2: No. of Zero FIRs Received | F2: Pending to Re-Register | G2: Raw Value | H2: Marks
A3: 1 | B3: A.Koduru | C3: 0 | D3: 0 | E3: 0 | F3: 0 | G3: 100 | H3: =G3*5% -> 5
A4: 2 | B4: Anakapalli Rural | C4: 0 | D4: 0 | E4: 0 | F4: 0 | G4: 100 | H4: =G4*5% -> 5
A5: 3 | B5: Anakapalli Town | C5: 0 | D5: 0 | E5: 0 | F5: 0 | G5: 100 | H5: =G5*5% -> 5
A6: 4 | B6: Anakapalli Traffic | C6: 0 | D6: 0 | E6: 0 | F6: 0 | G6: 100 | H6: =G6*5% -> 5
A7: 5 | B7: Atchutapuram | C7: 0 | D7: 0 | E7: 0 | F7: 0 | G7: 100 | H7: =G7*5% -> 5
A8: 6 | B8: Butchiyyapeta | C8: 0 | D8: 0 | E8: 0 | F8: 0 | G8: 100 | H8: =G8*5% -> 5
A9: 7 | B9: Cheedikada | C9: 0 | D9: 0 | E9: 0 | F9: 0 | G9: 100 | H9: =G9*5% -> 5
A10: 8 | B10: Chodavaram | C10: 0 | D10: 0 | E10: 0 | F10: 0 | G10: 100 | H10: =G10*5% -> 5
A11: 9 | B11: Devarapalli | C11: 0 | D11: 0 | E11: 0 | F11: 0 | G11: 100 | H11: =G11*5% -> 5
A12: 10 | B12: Golugonda | C12: 0 | D12: 0 | E12: 0 | F12: 0 | G12: 100 | H12: =G12*5% -> 5
A13: 11 | B13: K.D.Peta | C13: 0 | D13: 0 | E13: 0 | F13: 0 | G13: 100 | H13: =G13*5% -> 5
A14: 12 | B14: K.Kotapadu | C14: 0 | D14: 0 | E14: 0 | F14: 0 | G14: 100 | H14: =G14*5% -> 5
... A35: 33 | B35: Yelamanchili Traffic | C35: 0 | D35: 0 | E35: 0 | F35: 0 | G35: 100 | H35: =G35*5% -> 5

Sheet 9_CITIZEN_PORTAL
A1: Citizen Portal Petitions Status from 01-01-2015 to 15-09-2026 - (5 % - Marks)
A2: S.No | B2: PS NAME | C2: Total Online Petitions | D2: Total Disposal Petitions | E2: Total Pending Petitions | F2: Pending % | G2: Raw Value | H2: Marks
A3: 1 | B3: A.Koduru | C3: 5 | D3: 5 | E3: =C3-D3 -> 0 | F3: =IF(C3=0,0,(E3*100/C3)) -> 0 | G3: =100-F3 -> 100 | H3: =G3*5% -> 5
A4: 2 | B4: Anakapalli Rural | C4: 36 | D4: 36 | E4: =C4-D4 -> 0 | F4: =IF(C4=0,0,(E4*100/C4)) -> 0 | G4: =100-F4 -> 100 | H4: =G4*5% -> 5
A5: 3 | B5: Anakapalli Town | C5: 72 | D5: 72 | E5: =C5-D5 -> 0 | F5: =IF(C5=0,0,(E5*100/C5)) -> 0 | G5: =100-F5 -> 100 | H5: =G5*5% -> 5
A6: 4 | B6: Anakapalli Traffic | C6: 1 | D6: 1 | E6: =C6-D6 -> 0 | F6: =IF(C6=0,0,(E6*100/C6)) -> 0 | G6: =100-F6 -> 100 | H6: =G6*5% -> 5
A7: 5 | B7: Atchutapuram | C7: 17 | D7: 17 | E7: =C7-D7 -> 0 | F7: =IF(C7=0,0,(E7*100/C7)) -> 0 | G7: =100-F7 -> 100 | H7: =G7*5% -> 5
A8: 6 | B8: Butchiyyapeta | C8: 4 | D8: 4 | E8: =C8-D8 -> 0 | F8: =IF(C8=0,0,(E8*100/C8)) -> 0 | G8: =100-F8 -> 100 | H8: =G8*5% -> 5
A9: 7 | B9: Cheedikada | C9: 18 | D9: 18 | E9: =C9-D9 -> 0 | F9: =IF(C9=0,0,(E9*100/C9)) -> 0 | G9: =100-F9 -> 100 | H9: =G9*5% -> 5
A10: 8 | B10: Chodavaram | C10: 12 | D10: 12 | E10: =C10-D10 -> 0 | F10: =IF(C10=0,0,(E10*100/C10)) -> 0 | G10: =100-F10 -> 100 | H10: =G10*5% -> 5
A11: 9 | B11: Devarapalli | C11: 3 | D11: 3 | E11: =C11-D11 -> 0 | F11: =IF(C11=0,0,(E11*100/C11)) -> 0 | G11: =100-F11 -> 100 | H11: =G11*5% -> 5
A12: 10 | B12: Golugonda | C12: 6 | D12: 6 | E12: =C12-D12 -> 0 | F12: =IF(C12=0,0,(E12*100/C12)) -> 0 | G12: =100-F12 -> 100 | H12: =G12*5% -> 5
A13: 11 | B13: K.D.Peta | C13: 7 | D13: 7 | E13: =C13-D13 -> 0 | F13: =IF(C13=0,0,(E13*100/C13)) -> 0 | G13: =100-F13 -> 100 | H13: =G13*5% -> 5
A14: 12 | B14: K.Kotapadu | C14: 3 | D14: 3 | E14: =C14-D14 -> 0 | F14: =IF(C14=0,0,(E14*100/C14)) -> 0 | G14: =100-F14 -> 100 | H14: =G14*5% -> 5
... A35: 33 | B35: Yelamanchili Traffic | C35: 5 | D35: 5 | E35: =C35-D35 -> 0 | F35: =IF(C35=0,0,(E35*100/C35)) -> 0 | G35: =100-F35 -> 100 | H35: =G35*5% -> 5
A36: Grand Total | C36: =SUM(C3:C35) -> 451 | D36: =SUM(D3:D35) -> 451 | E36: =SUM(E3:E35) -> 0 | F36: =AVERAGE(F3:F35) -> 0 | G36: =AVERAGE(G3:G35) -> 100 | H36: =AVERAGE(H3:H35) -> 5

Sheet 10_ESAKSHYA
A1: E SAKSHYA IDS CREATED FOR FIRS FROM 01-07-2024 TO 15-09-2026- (5 % - Marks)
A2: S.NO (A) | B2: PS NAME (B) | C2: TOTAL FIRS ( C ) | D2: TOTAL SIDs CREATED ( D ) | E2: FIRS HAVING SID (F ) | F2: FIRS NOT HAVING SID (G) | G2: E SAKSHYA COMPLIANCE % F*100/C RAW VALUE | H2: Marks
A4: 1 | B4: A.Koduru | C4: 210 | D4: 421 | E4: 239 | F4: 0 | G4: =IF((E4*100)/C4>100,100,(E4*100)/C4) -> 100 | H4: =G4*5% -> 5
A5: 2 | B5: Anakapalli Rural | C5: 544 | D5: 469 | E5: 232 | F5: 312 | G5: =IF((E5*100)/C5>100,100,(E5*100)/C5) -> 42.647059 | H5: =G5*5% -> 2.1323529
A6: 3 | B6: Anakapalli Town | C6: 707 | D6: 488 | E6: 266 | F6: 441 | G6: =IF((E6*100)/C6>100,100,(E6*100)/C6) -> 37.623762 | H6: =G6*5% -> 1.8811881
A7: 4 | B7: Anakapalli Traffic | C7: 231 | D7: 324 | E7: 123 | F7: 108 | G7: =IF((E7*100)/C7>100,100,(E7*100)/C7) -> 53.246753 | H7: =G7*5% -> 2.6623377
A8: 5 | B8: Atchutapuram | C8: 571 | D8: 356 | E8: 298 | F8: 273 | G8: =IF((E8*100)/C8>100,100,(E8*100)/C8) -> 52.189142 | H8: =G8*5% -> 2.6094571
A9: 6 | B9: Butchiyyapeta | C9: 340 | D9: 366 | E9: 333 | F9: 7 | G9: =IF((E9*100)/C9>100,100,(E9*100)/C9) -> 97.941176 | H9: =G9*5% -> 4.8970588
A10: 7 | B10: Cheedikada | C10: 220 | D10: 264 | E10: 215 | F10: 5 | G10: =IF((E10*100)/C10>100,100,(E10*100)/C10) -> 97.727273 | H10: =G10*5% -> 4.8863636
A11: 8 | B11: Chodavaram | C11: 648 | D11: 565 | E11: 419 | F11: 229 | G11: =IF((E11*100)/C11>100,100,(E11*100)/C11) -> 64.660494 | H11: =G11*5% -> 3.2330247
A12: 9 | B12: Devarapalli | C12: 354 | D12: 357 | E12: 302 | F12: 52 | G12: =IF((E12*100)/C12>100,100,(E12*100)/C12) -> 85.310734 | H12: =G12*5% -> 4.2655367
A13: 10 | B13: Golugonda | C13: 260 | D13: 188 | E13: 156 | F13: 104 | G13: =IF((E13*100)/C13>100,100,(E13*100)/C13) -> 60 | H13: =G13*5% -> 3
A14: 11 | B14: K.D.Peta | C14: 177 | D14: 164 | E14: 153 | F14: 24 | G14: =IF((E14*100)/C14>100,100,(E14*100)/C14) -> 86.440678 | H14: =G14*5% -> 4.3220339
A15: 12 | B15: K.Kotapadu | C15: 228 | D15: 249 | E15: 167 | F15: 61 | G15: =IF((E15*100)/C15>100,100,(E15*100)/C15) -> 73.245614 | H15: =G15*5% -> 3.6622807
... A36: 33 | B36: Yelamanchili Traffic | C36: 45 | D36: 47 | E36: 38 | F36: 7 | G36: =IF((E36*100)/C36>100,100,(E36*100)/C36) -> 84.444444 | H36: =G36*5% -> 4.2222222
A37: Grand Total | C37: =SUM(C4:C36) -> 12484 | D37: =SUM(D4:D36) -> 10918 | E37: =SUM(E4:E36) -> 7767 | F37: =SUM(F4:F36) -> 4746 | G37: =AVERAGE(G4:G36) -> 65.871392 | H37: =AVERAGE(H4:H36) -> 3.2935696

Sheet 11_CRIMAC
A1: CRI-MAC APPLICATION ALERTS ENTRY FROM 09-09-2026 TO 15-09-2026 (5 % - Marks)
A2: S.No. | B2: PS Name | C2: Total FIRS Registered | D2: Total no. of Alerts | E2: Raw Value | F2: Marks
A3: 1 | B3: A.Koduru | C3: 0 | D3: 2 | E3: =IF(AND(D3>=C3),100,0) -> 100 | F3: =E3*5% -> 5
A4: 2 | B4: Anakapalli Rural | C4: 4 | D4: 16 | E4: =IF(AND(D4>=C4),100,0) -> 100 | F4: =E4*5% -> 5
A5: 3 | B5: Anakapalli Town | C5: 1 | D5: 5 | E5: =IF(AND(D5>=C5),100,0) -> 100 | F5: =E5*5% -> 5
A6: 4 | B6: Anakapalli Traffic | C6: 4 | D6: 4 | E6: =IF(AND(D6>=C6),100,0) -> 100 | F6: =E6*5% -> 5
A7: 5 | B7: Atchutapuram | C7: 9 | D7: 9 | E7: =IF(AND(D7>=C7),100,0) -> 100 | F7: =E7*5% -> 5
A8: 6 | B8: Butchiyyapeta | C8: 3 | D8: 28 | E8: =IF(AND(D8>=C8),100,0) -> 100 | F8: =E8*5% -> 5
A9: 7 | B9: Cheedikada | C9: 2 | D9: 25 | E9: =IF(AND(D9>=C9),100,0) -> 100 | F9: =E9*5% -> 5
A10: 8 | B10: Chodavaram | C10: 3 | D10: 13 | E10: =IF(AND(D10>=C10),100,0) -> 100 | F10: =E10*5% -> 5
A11: 9 | B11: Devarapalli | C11: 0 | D11: 26 | E11: =IF(AND(D11>=C11),100,0) -> 100 | F11: =E11*5% -> 5
A12: 10 | B12: Golugonda | C12: 2 | D12: 16 | E12: =IF(AND(D12>=C12),100,0) -> 100 | F12: =E12*5% -> 5
A13: 11 | B13: K.D.Peta | C13: 1 | D13: 11 | E13: =IF(AND(D13>=C13),100,0) -> 100 | F13: =E13*5% -> 5
A14: 12 | B14: K.Kotapadu | C14: 3 | D14: 33 | E14: =IF(AND(D14>=C14),100,0) -> 100 | F14: =E14*5% -> 5
... A35: 33 | B35: Yelamanchili Traffic | C35: 2 | D35: 2 | E35: =IF(AND(D35>=C35),100,0) -> 100 | F35: =E35*5% -> 5
A36: TOTAL NUMBER OF ALERTS | C36: =SUM(C3:C35) -> 87 | D36: =SUM(D3:D35) -> 523 | E36: =AVERAGE(E3:E35) -> 100 | F36: =AVERAGE(F3:F35) -> 5

Sheet 12_CEIR
A1: CEIR PS WISE TRACIBILITY, RECOVERIES, ACCURACY SCORE , VOLUME SCORE , FINAL SCORE FROM 01-01-2025 TO TILL DATE (DOT - NEW GUIDELINES) - (5% - Marks)
A2: SNO | B2: PS Name | C2: Total Block Requests Received | D2: Blocked Requests (as on report generation date) | E2: Unblocked Requests (as on report generation date) | F2: Total Traceability Generated (as on report generation date) | G2: Unrecovered Traceability Available (as on report generation date) | H2: Recovered handsets | I2: Accuracy score (as per recovery %) Accuracy score = (Total Recovered handsets by PS so far x 100)/Totaltraceability generated so far (* so far means cumulative figure at the time of computing the score) | J2: Volume Score (as per no. of handsets recovered) Volume score = ((Total Recovered handsets so far by PS – Minimum No. of handsets recovered by any PS so far in the District) x 100)/ (Maximum No.of handsets recovered by any PS so far in the DIstrict – Minimum No. ofhandsets recovered by any PS so far in the DIstrict) | K2: Final Score 70: 30 Final score = Accuracy score * 0.7 + Volume score*0.3 | L2: Marks
A3: 1 | B3: A.Koduru | C3: 43 | D3: 31 | E3: 12 | F3: 25 | G3: 13 | H3: =E3 -> 12 | I3: =IFERROR(E3*100/F3,0) -> 48 | J3: =(I3-MIN($I$3:$I$35))*100/(MAX($I$3:$I$35)-MIN($I$3:$I$35)) -> 63 | K3: =IF(C3=0,50,IF(I3*0.7+J3*0.3>100,100,I3*0.7+J3*0.3)) -> 52.5 | L3: =K3*5% -> 2.625
A4: 2 | B4: Anakapalli Rural | C4: 271 | D4: 188 | E4: 83 | F4: 149 | G4: 72 | H4: =E4 -> 83 | I4: =IFERROR(E4*100/F4,0) -> 55.704698 | J4: =(I4-MIN($I$3:$I$35))*100/(MAX($I$3:$I$35)-MIN($I$3:$I$35)) -> 73.112416 | K4: =IF(C4=0,50,IF(I4*0.7+J4*0.3>100,100,I4*0.7+J4*0.3)) -> 60.927013 | L4: =K4*5% -> 3.0463507
A5: 3 | B5: Anakapalli Town | C5: 1376 | D5: 956 | E5: 420 | F5: 709 | G5: 321 | H5: =E5 -> 420 | I5: =IFERROR(E5*100/F5,0) -> 59.238364 | J5: =(I5-MIN($I$3:$I$35))*100/(MAX($I$3:$I$35)-MIN($I$3:$I$35)) -> 77.750353 | K5: =IF(C5=0,50,IF(I5*0.7+J5*0.3>100,100,I5*0.7+J5*0.3)) -> 64.791961 | L5: =K5*5% -> 3.239598
A6: 4 | B6: Anakapalli Traffic | C6: 0 | D6: 0 | E6: 0 | F6: 0 | G6: 0 | H6: =E6 -> 0 | I6: =IFERROR(E6*100/F6,0) -> 0 | J6: =(I6-MIN($I$3:$I$35))*100/(MAX($I$3:$I$35)-MIN($I$3:$I$35)) -> 0 | K6: =IF(C6=0,50,IF(I6*0.7+J6*0.3>100,100,I6*0.7+J6*0.3)) -> 50 | L6: =K6*5% -> 2.5
A7: 5 | B7: Atchutapuram | C7: 339 | D7: 223 | E7: 116 | F7: 185 | G7: 77 | H7: =E7 -> 116 | I7: =IFERROR(E7*100/F7,0) -> 62.702703 | J7: =(I7-MIN($I$3:$I$35))*100/(MAX($I$3:$I$35)-MIN($I$3:$I$35)) -> 82.297297 | K7: =IF(C7=0,50,IF(I7*0.7+J7*0.3>100,100,I7*0.7+J7*0.3)) -> 68.581081 | L7: =K7*5% -> 3.4290541
A8: 6 | B8: Butchiyyapeta | C8: 144 | D8: 107 | E8: 37 | F8: 68 | G8: 36 | H8: =E8 -> 37 | I8: =IFERROR(E8*100/F8,0) -> 54.411765 | J8: =(I8-MIN($I$3:$I$35))*100/(MAX($I$3:$I$35)-MIN($I$3:$I$35)) -> 71.415441 | K8: =IF(C8=0,50,IF(I8*0.7+J8*0.3>100,100,I8*0.7+J8*0.3)) -> 59.512868 | L8: =K8*5% -> 2.9756434
A9: 7 | B9: Cheedikada | C9: 45 | D9: 28 | E9: 17 | F9: 25 | G9: 9 | H9: =E9 -> 17 | I9: =IFERROR(E9*100/F9,0) -> 68 | J9: =(I9-MIN($I$3:$I$35))*100/(MAX($I$3:$I$35)-MIN($I$3:$I$35)) -> 89.25 | K9: =IF(C9=0,50,IF(I9*0.7+J9*0.3>100,100,I9*0.7+J9*0.3)) -> 74.375 | L9: =K9*5% -> 3.71875
A10: 8 | B10: Chodavaram | C10: 331 | D10: 240 | E10: 91 | F10: 164 | G10: 77 | H10: =E10 -> 91 | I10: =IFERROR(E10*100/F10,0) -> 55.487805 | J10: =(I10-MIN($I$3:$I$35))*100/(MAX($I$3:$I$35)-MIN($I$3:$I$35)) -> 72.827744 | K10: =IF(C10=0,50,IF(I10*0.7+J10*0.3>100,100,I10*0.7+J10*0.3)) -> 60.689787 | L10: =K10*5% -> 3.0344893
A11: 9 | B11: Devarapalli | C11: 75 | D11: 47 | E11: 28 | F11: 48 | G11: 20 | H11: =E11 -> 28 | I11: =IFERROR(E11*100/F11,0) -> 58.333333 | J11: =(I11-MIN($I$3:$I$35))*100/(MAX($I$3:$I$35)-MIN($I$3:$I$35)) -> 76.5625 | K11: =IF(C11=0,50,IF(I11*0.7+J11*0.3>100,100,I11*0.7+J11*0.3)) -> 63.802083 | L11: =K11*5% -> 3.1901042
A12: 10 | B12: Golugonda | C12: 37 | D12: 31 | E12: 6 | F12: 25 | G12: 19 | H12: =E12 -> 6 | I12: =IFERROR(E12*100/F12,0) -> 24 | J12: =(I12-MIN($I$3:$I$35))*100/(MAX($I$3:$I$35)-MIN($I$3:$I$35)) -> 31.5 | K12: =IF(C12=0,50,IF(I12*0.7+J12*0.3>100,100,I12*0.7+J12*0.3)) -> 26.25 | L12: =K12*5% -> 1.3125
A13: 11 | B13: K.D.Peta | C13: 87 | D13: 56 | E13: 31 | F13: 49 | G13: 23 | H13: =E13 -> 31 | I13: =IFERROR(E13*100/F13,0) -> 63.265306 | J13: =(I13-MIN($I$3:$I$35))*100/(MAX($I$3:$I$35)-MIN($I$3:$I$35)) -> 83.035714 | K13: =IF(C13=0,50,IF(I13*0.7+J13*0.3>100,100,I13*0.7+J13*0.3)) -> 69.196429 | L13: =K13*5% -> 3.4598214
A14: 12 | B14: K.Kotapadu | C14: 46 | D14: 36 | E14: 10 | F14: 22 | G14: 12 | H14: =E14 -> 10 | I14: =IFERROR(E14*100/F14,0) -> 45.454545 | J14: =(I14-MIN($I$3:$I$35))*100/(MAX($I$3:$I$35)-MIN($I$3:$I$35)) -> 59.659091 | K14: =IF(C14=0,50,IF(I14*0.7+J14*0.3>100,100,I14*0.7+J14*0.3)) -> 49.715909 | L14: =K14*5% -> 2.4857955
... A35: 33 | B35: Yelamanchili Traffic | C35: 0 | D35: 0 | E35: 0 | F35: 0 | G35: 0 | H35: =E35 -> 0 | I35: =IFERROR(E35*100/F35,0) -> 0 | J35: =(I35-MIN($I$3:$I$35))*100/(MAX($I$3:$I$35)-MIN($I$3:$I$35)) -> 0 | K35: =IF(C35=0,50,IF(I35*0.7+J35*0.3>100,100,I35*0.7+J35*0.3)) -> 50 | L35: =K35*5% -> 2.5
A36: GRAND TOTAL | C36: =SUM(C3:C35) -> 5737 | D36: =SUM(D3:D35) -> 4026 | E36: =SUM(E3:E35) -> 1711 | F36: =SUM(F3:F35) -> 3026 | G36: =SUM(G3:G35) -> 1448 | H36: =SUM(H3:H35) -> 1711 | I36: =AVERAGE(I3:I35) -> 49.694891 | J36: =AVERAGE(J3:J35) -> 65.224544 | K36: =AVERAGE(K3:K35) -> 58.899241 | L36: =AVERAGE(L3:L35) -> 2.9449621

Sheet 13_EPROSEC
A1: Usage Status of eProsecution application by the Police Stations
A2: FROM 09-09-2026 TO 15-09-2026 - (5 % Marks)
A3: S.No | B3: POLICE STATION | C3: Total Cases Charged | D3: No. of cases eProc created | E3: Raw Value if UI = 0 ( 100 points) | F3: Marks
A4: 1 | B4: A.Koduru | C4: 0 | D4: 0 | E4: =IF(C4=0,100,D4*100/C4) -> 100 | F4: =E4*5% -> 5
A5: 2 | B5: Anakapalli Rural | C5: 6 | D5: 1 | E5: =IF(C5=0,100,D5*100/C5) -> 16.666667 | F5: =E5*5% -> 0.83333333
A6: 3 | B6: Anakapalli Town | C6: 8 | D6: 1 | E6: =IF(C6=0,100,D6*100/C6) -> 12.5 | F6: =E6*5% -> 0.625
A7: 4 | B7: Anakapalli Traffic | C7: 2 | D7: 2 | E7: =IF(C7=0,100,D7*100/C7) -> 100 | F7: =E7*5% -> 5
A8: 5 | B8: Atchutapuram | C8: 4 | D8: 1 | E8: =IF(C8=0,100,D8*100/C8) -> 25 | F8: =E8*5% -> 1.25
A9: 6 | B9: Butchiyyapeta | C9: 2 | D9: 2 | E9: =IF(C9=0,100,D9*100/C9) -> 100 | F9: =E9*5% -> 5
A10: 7 | B10: Cheedikada | C10: 1 | D10: 1 | E10: =IF(C10=0,100,D10*100/C10) -> 100 | F10: =E10*5% -> 5
A11: 8 | B11: Chodavaram | C11: 6 | D11: 2 | E11: =IF(C11=0,100,D11*100/C11) -> 33.333333 | F11: =E11*5% -> 1.6666667
A12: 9 | B12: Devarapalli | C12: 1 | D12: 1 | E12: =IF(C12=0,100,D12*100/C12) -> 100 | F12: =E12*5% -> 5
A13: 10 | B13: Golugonda | C13: 3 | D13: 2 | E13: =IF(C13=0,100,D13*100/C13) -> 66.666667 | F13: =E13*5% -> 3.3333333
A14: 11 | B14: K.D.Peta | C14: 1 | D14: 1 | E14: =IF(C14=0,100,D14*100/C14) -> 100 | F14: =E14*5% -> 5
A15: 12 | B15: K.Kotapadu | C15: 1 | D15: 1 | E15: =IF(C15=0,100,D15*100/C15) -> 100 | F15: =E15*5% -> 5
... A36: 33 | B36: Yelamanchili Traffic | C36: 4 | D36: 4 | E36: =IF(C36=0,100,D36*100/C36) -> 100 | F36: =E36*5% -> 5

Sheet 14_FIR_CS_COURT
A1: FIRs (ONLY BNS) Consumed in Courts Status from 01-07-2024 to 15-09-2026- (5 % - Marks)
A2: S.No | B2: POLICE STATION | C2: Total FIRs Registered | D2: FIRs Consumed in Court | E2: FIR Raw Value | F2: Marks (2.5) | G2: Charge sheets Filed | H2: Chargesheets Consumed in Court | I2: Charge Sheet Raw Value | J2: Marks (2.5) | K2: TOTAL MARKS (5) | L2: Final Raw Value
A3: 1 | B3: A.Koduru | C3: 107 | D3: 95 | E3: =IFERROR(D3*100/C3,"") -> 88.785047 | F3: =E3*2.5% -> 2.2196262 | G3: 94 | H3: 62 | I3: =IFERROR(H3*100/G3,"") -> 65.957447 | J3: =I3*2.5% -> 1.6489362 | K3: =F3+J3 -> 3.8685623 | L3: =IFERROR((E3+I3)/2,"") -> 77.371247
A4: 2 | B4: Anakapalli Rural | C4: 313 | D4: 154 | E4: =IFERROR(D4*100/C4,"") -> 49.201278 | F4: =E4*2.5% -> 1.2300319 | G4: 221 | H4: 209 | I4: =IFERROR(H4*100/G4,"") -> 94.570136 | J4: =I4*2.5% -> 2.3642534 | K4: =F4+J4 -> 3.5942853 | L4: =IFERROR((E4+I4)/2,"") -> 71.885707
A5: 3 | B5: Anakapalli Town | C5: 304 | D5: 148 | E5: =IFERROR(D5*100/C5,"") -> 48.684211 | F5: =E5*2.5% -> 1.2171053 | G5: 199 | H5: 176 | I5: =IFERROR(H5*100/G5,"") -> 88.442211 | J5: =I5*2.5% -> 2.2110553 | K5: =F5+J5 -> 3.4281605 | L5: =IFERROR((E5+I5)/2,"") -> 68.563211
A6: 4 | B6: Anakapalli Traffic | C6: 231 | D6: 136 | E6: =IFERROR(D6*100/C6,"") -> 58.874459 | F6: =E6*2.5% -> 1.4718615 | G6: 201 | H6: 185 | I6: =IFERROR(H6*100/G6,"") -> 92.039801 | J6: =I6*2.5% -> 2.300995 | K6: =F6+J6 -> 3.7728565 | L6: =IFERROR((E6+I6)/2,"") -> 75.45713
A7: 5 | B7: Atchutapuram | C7: 324 | D7: 261 | E7: =IFERROR(D7*100/C7,"") -> 80.555556 | F7: =E7*2.5% -> 2.0138889 | G7: 245 | H7: 201 | I7: =IFERROR(H7*100/G7,"") -> 82.040816 | J7: =I7*2.5% -> 2.0510204 | K7: =F7+J7 -> 4.0649093 | L7: =IFERROR((E7+I7)/2,"") -> 81.298186
A8: 6 | B8: Butchiyyapeta | C8: 164 | D8: 130 | E8: =IFERROR(D8*100/C8,"") -> 79.268293 | F8: =E8*2.5% -> 1.9817073 | G8: 134 | H8: 119 | I8: =IFERROR(H8*100/G8,"") -> 88.80597 | J8: =I8*2.5% -> 2.2201493 | K8: =F8+J8 -> 4.2018566 | L8: =IFERROR((E8+I8)/2,"") -> 84.037131
A9: 7 | B9: Cheedikada | C9: 102 | D9: 81 | E9: =IFERROR(D9*100/C9,"") -> 79.411765 | F9: =E9*2.5% -> 1.9852941 | G9: 79 | H9: 68 | I9: =IFERROR(H9*100/G9,"") -> 86.075949 | J9: =I9*2.5% -> 2.1518987 | K9: =F9+J9 -> 4.1371929 | L9: =IFERROR((E9+I9)/2,"") -> 82.743857
A10: 8 | B10: Chodavaram | C10: 369 | D10: 282 | E10: =IFERROR(D10*100/C10,"") -> 76.422764 | F10: =E10*2.5% -> 1.9105691 | G10: 248 | H10: 220 | I10: =IFERROR(H10*100/G10,"") -> 88.709677 | J10: =I10*2.5% -> 2.2177419 | K10: =F10+J10 -> 4.128311 | L10: =IFERROR((E10+I10)/2,"") -> 82.566221
A11: 9 | B11: Devarapalli | C11: 178 | D11: 133 | E11: =IFERROR(D11*100/C11,"") -> 74.719101 | F11: =E11*2.5% -> 1.8679775 | G11: 148 | H11: 119 | I11: =IFERROR(H11*100/G11,"") -> 80.405405 | J11: =I11*2.5% -> 2.0101351 | K11: =F11+J11 -> 3.8781127 | L11: =IFERROR((E11+I11)/2,"") -> 77.562253
A12: 10 | B12: Golugonda | C12: 135 | D12: 107 | E12: =IFERROR(D12*100/C12,"") -> 79.259259 | F12: =E12*2.5% -> 1.9814815 | G12: 113 | H12: 85 | I12: =IFERROR(H12*100/G12,"") -> 75.221239 | J12: =I12*2.5% -> 1.880531 | K12: =F12+J12 -> 3.8620125 | L12: =IFERROR((E12+I12)/2,"") -> 77.240249
A13: 11 | B13: K.D.Peta | C13: 69 | D13: 57 | E13: =IFERROR(D13*100/C13,"") -> 82.608696 | F13: =E13*2.5% -> 2.0652174 | G13: 59 | H13: 48 | I13: =IFERROR(H13*100/G13,"") -> 81.355932 | J13: =I13*2.5% -> 2.0338983 | K13: =F13+J13 -> 4.0991157 | L13: =IFERROR((E13+I13)/2,"") -> 81.982314
A14: 12 | B14: K.Kotapadu | C14: 115 | D14: 92 | E14: =IFERROR(D14*100/C14,"") -> 80 | F14: =E14*2.5% -> 2 | G14: 93 | H14: 70 | I14: =IFERROR(H14*100/G14,"") -> 75.268817 | J14: =I14*2.5% -> 1.8817204 | K14: =F14+J14 -> 3.8817204 | L14: =IFERROR((E14+I14)/2,"") -> 77.634409
... A35: 33 | B35: Yelamanchili Traffic | C35: 38 | D35: 38 | E35: =IFERROR(D35*100/C35,"") -> 100 | F35: =E35*2.5% -> 2.5 | G35: 38 | H35: 0 | I35: =IFERROR(H35*100/G35,"") -> 0 | J35: =I35*2.5% -> 0 | K35: =F35+J35 -> 2.5 | L35: =IFERROR((E35+I35)/2,"") -> 50
A36: GRAND TOTAL | C36: =SUM(C3:C35) -> 6677 | D36: =SUM(D3:D35) -> 4554 | E36: =IFERROR(D36*100/C36,"") -> 68.204283 | F36: =IFERROR(E36*100/D36,"") -> 1.4976786 | G36: =SUM(G3:G35) -> 4965 | H36: =SUM(H3:H35) -> 4179 | I36: =IFERROR(H36*100/G36,"") -> 84.169184 | J36: =AVERAGE(J3:J35) -> 2.0320465 | K36: =F36+J36 -> 3.5297251 | L36: =IFERROR((E36+I36)/2,"") -> 76.186734

Sheet 15_EOFFICE
A1: E OFFICE - FILE DISPOSAL TIME TAKEN REPORT (DESIGNATION WISE) ( URBAN - 35 PER WEEK AND RURAL -21 PER WEEK)
A2: Period : | C2: FROM 09-09-2026 TO 15-09-2026 - (5 % Marks)
A3: S.No. | B3: PS NAME | C3: Total Disposed Files | D3: Total Disposed files Raw Value | E3: Total Disposed Files Marks (2.5) | F3: Average Response time (Days HH:MM:SS) | G3: Hours Convertion to (HH:MM:SS) | H3: Average Response time Raw Value | I3: Average Response time Marks | J3: Total E Office Raw Value | K3: Total Marks | L3: U/R
A4: 1 | B4: A.Koduru | C4: 25 | D4: =IF(L4="U", IF(C4>=35,100,ROUND(C4/35*100,2)), IF(L4="R", IF(C4>=21,100,ROUND(C4/21*100,2)), "" ) ) -> 100 | E4: =D4*2.5% -> 2.5 | F4: 0 days 00:43:21 | G4: =IF(OR(F4="",F4=0,LEFT(F4,1)="-"),0,TEXT((VALUE(LEFT(F4,FIND(" day",F4)-1))+TIMEVALUE(RIGHT(F4,8))),"[h]:mm:ss")) -> 0:43:21 | H4: =IF(OR(G4="",G4="0",G4=0),0, IF(VALUE(LEFT(G4,FIND(":",G4)-1))<24,100, IF(VALUE(LEFT(G4,FIND(":",G4)-1))<48,50, IF(VALUE(LEFT(G4,FIND(":",G4)-1))<72,25,0)))) -> 100 | I4: =H4*2.5% -> 2.5 | J4: =(D4+H4)/2 -> 100 | K4: =J4*5% -> 5 | L4: R
A5: 2 | B5: Anakapalli Rural | C5: 50 | D5: =IF(L5="U", IF(C5>=35,100,ROUND(C5/35*100,2)), IF(L5="R", IF(C5>=21,100,ROUND(C5/21*100,2)), "" ) ) -> 100 | E5: =D5*2.5% -> 2.5 | F5: 0 days 00:43:21 | G5: =IF(OR(F5="",F5=0,LEFT(F5,1)="-"),0,TEXT((VALUE(LEFT(F5,FIND(" day",F5)-1))+TIMEVALUE(RIGHT(F5,8))),"[h]:mm:ss")) -> 0:43:21 | H5: =IF(OR(G5="",G5="0",G5=0),0, IF(VALUE(LEFT(G5,FIND(":",G5)-1))<24,100, IF(VALUE(LEFT(G5,FIND(":",G5)-1))<48,50, IF(VALUE(LEFT(G5,FIND(":",G5)-1))<72,25,0)))) -> 100 | I5: =H5*2.5% -> 2.5 | J5: =(D5+H5)/2 -> 100 | K5: =J5*5% -> 5 | L5: U
A6: 3 | B6: Anakapalli Town | C6: 50 | D6: =IF(L6="U", IF(C6>=35,100,ROUND(C6/35*100,2)), IF(L6="R", IF(C6>=21,100,ROUND(C6/21*100,2)), "" ) ) -> 100 | E6: =D6*2.5% -> 2.5 | F6: 0 days 00:43:21 | G6: =IF(OR(F6="",F6=0,LEFT(F6,1)="-"),0,TEXT((VALUE(LEFT(F6,FIND(" day",F6)-1))+TIMEVALUE(RIGHT(F6,8))),"[h]:mm:ss")) -> 0:43:21 | H6: =IF(OR(G6="",G6="0",G6=0),0, IF(VALUE(LEFT(G6,FIND(":",G6)-1))<24,100, IF(VALUE(LEFT(G6,FIND(":",G6)-1))<48,50, IF(VALUE(LEFT(G6,FIND(":",G6)-1))<72,25,0)))) -> 100 | I6: =H6*2.5% -> 2.5 | J6: =(D6+H6)/2 -> 100 | K6: =J6*5% -> 5 | L6: U
A7: 4 | B7: Anakapalli Traffic | C7: 50 | D7: =IF(L7="U", IF(C7>=35,100,ROUND(C7/35*100,2)), IF(L7="R", IF(C7>=21,100,ROUND(C7/21*100,2)), "" ) ) -> 100 | E7: =D7*2.5% -> 2.5 | F7: 0 days 00:43:21 | G7: =IF(OR(F7="",F7=0,LEFT(F7,1)="-"),0,TEXT((VALUE(LEFT(F7,FIND(" day",F7)-1))+TIMEVALUE(RIGHT(F7,8))),"[h]:mm:ss")) -> 0:43:21 | H7: =IF(OR(G7="",G7="0",G7=0),0, IF(VALUE(LEFT(G7,FIND(":",G7)-1))<24,100, IF(VALUE(LEFT(G7,FIND(":",G7)-1))<48,50, IF(VALUE(LEFT(G7,FIND(":",G7)-1))<72,25,0)))) -> 100 | I7: =H7*2.5% -> 2.5 | J7: =(D7+H7)/2 -> 100 | K7: =J7*5% -> 5 | L7: U
A8: 5 | B8: Atchutapuram | C8: 50 | D8: =IF(L8="U", IF(C8>=35,100,ROUND(C8/35*100,2)), IF(L8="R", IF(C8>=21,100,ROUND(C8/21*100,2)), "" ) ) -> 100 | E8: =D8*2.5% -> 2.5 | F8: 0 days 00:43:21 | G8: =IF(OR(F8="",F8=0,LEFT(F8,1)="-"),0,TEXT((VALUE(LEFT(F8,FIND(" day",F8)-1))+TIMEVALUE(RIGHT(F8,8))),"[h]:mm:ss")) -> 0:43:21 | H8: =IF(OR(G8="",G8="0",G8=0),0, IF(VALUE(LEFT(G8,FIND(":",G8)-1))<24,100, IF(VALUE(LEFT(G8,FIND(":",G8)-1))<48,50, IF(VALUE(LEFT(G8,FIND(":",G8)-1))<72,25,0)))) -> 100 | I8: =H8*2.5% -> 2.5 | J8: =(D8+H8)/2 -> 100 | K8: =J8*5% -> 5 | L8: U
A9: 6 | B9: Butchiyyapeta | C9: 25 | D9: =IF(L9="U", IF(C9>=35,100,ROUND(C9/35*100,2)), IF(L9="R", IF(C9>=21,100,ROUND(C9/21*100,2)), "" ) ) -> 100 | E9: =D9*2.5% -> 2.5 | F9: 0 days 00:43:21 | G9: =IF(OR(F9="",F9=0,LEFT(F9,1)="-"),0,TEXT((VALUE(LEFT(F9,FIND(" day",F9)-1))+TIMEVALUE(RIGHT(F9,8))),"[h]:mm:ss")) -> 0:43:21 | H9: =IF(OR(G9="",G9="0",G9=0),0, IF(VALUE(LEFT(G9,FIND(":",G9)-1))<24,100, IF(VALUE(LEFT(G9,FIND(":",G9)-1))<48,50, IF(VALUE(LEFT(G9,FIND(":",G9)-1))<72,25,0)))) -> 100 | I9: =H9*2.5% -> 2.5 | J9: =(D9+H9)/2 -> 100 | K9: =J9*5% -> 5 | L9: R
A10: 7 | B10: Cheedikada | C10: 25 | D10: =IF(L10="U", IF(C10>=35,100,ROUND(C10/35*100,2)), IF(L10="R", IF(C10>=21,100,ROUND(C10/21*100,2)), "" ) ) -> 100 | E10: =D10*2.5% -> 2.5 | F10: 0 days 00:43:21 | G10: =IF(OR(F10="",F10=0,LEFT(F10,1)="-"),0,TEXT((VALUE(LEFT(F10,FIND(" day",F10)-1))+TIMEVALUE(RIGHT(F10,8))),"[h]:mm:ss")) -> 0:43:21 | H10: =IF(OR(G10="",G10="0",G10=0),0, IF(VALUE(LEFT(G10,FIND(":",G10)-1))<24,100, IF(VALUE(LEFT(G10,FIND(":",G10)-1))<48,50, IF(VALUE(LEFT(G10,FIND(":",G10)-1))<72,25,0)))) -> 100 | I10: =H10*2.5% -> 2.5 | J10: =(D10+H10)/2 -> 100 | K10: =J10*5% -> 5 | L10: R
A11: 8 | B11: Chodavaram | C11: 50 | D11: =IF(L11="U", IF(C11>=35,100,ROUND(C11/35*100,2)), IF(L11="R", IF(C11>=21,100,ROUND(C11/21*100,2)), "" ) ) -> 100 | E11: =D11*2.5% -> 2.5 | F11: 0 days 00:43:21 | G11: =IF(OR(F11="",F11=0,LEFT(F11,1)="-"),0,TEXT((VALUE(LEFT(F11,FIND(" day",F11)-1))+TIMEVALUE(RIGHT(F11,8))),"[h]:mm:ss")) -> 0:43:21 | H11: =IF(OR(G11="",G11="0",G11=0),0, IF(VALUE(LEFT(G11,FIND(":",G11)-1))<24,100, IF(VALUE(LEFT(G11,FIND(":",G11)-1))<48,50, IF(VALUE(LEFT(G11,FIND(":",G11)-1))<72,25,0)))) -> 100 | I11: =H11*2.5% -> 2.5 | J11: =(D11+H11)/2 -> 100 | K11: =J11*5% -> 5 | L11: U
A12: 9 | B12: Devarapalli | C12: 43 | D12: =IF(L12="U", IF(C12>=35,100,ROUND(C12/35*100,2)), IF(L12="R", IF(C12>=21,100,ROUND(C12/21*100,2)), "" ) ) -> 100 | E12: =D12*2.5% -> 2.5 | F12: 0 days 00:43:21 | G12: =IF(OR(F12="",F12=0,LEFT(F12,1)="-"),0,TEXT((VALUE(LEFT(F12,FIND(" day",F12)-1))+TIMEVALUE(RIGHT(F12,8))),"[h]:mm:ss")) -> 0:43:21 | H12: =IF(OR(G12="",G12="0",G12=0),0, IF(VALUE(LEFT(G12,FIND(":",G12)-1))<24,100, IF(VALUE(LEFT(G12,FIND(":",G12)-1))<48,50, IF(VALUE(LEFT(G12,FIND(":",G12)-1))<72,25,0)))) -> 100 | I12: =H12*2.5% -> 2.5 | J12: =(D12+H12)/2 -> 100 | K12: =J12*5% -> 5 | L12: R
A13: 10 | B13: Golugonda | C13: 25 | D13: =IF(L13="U", IF(C13>=35,100,ROUND(C13/35*100,2)), IF(L13="R", IF(C13>=21,100,ROUND(C13/21*100,2)), "" ) ) -> 100 | E13: =D13*2.5% -> 2.5 | F13: 0 days 00:43:21 | G13: =IF(OR(F13="",F13=0,LEFT(F13,1)="-"),0,TEXT((VALUE(LEFT(F13,FIND(" day",F13)-1))+TIMEVALUE(RIGHT(F13,8))),"[h]:mm:ss")) -> 0:43:21 | H13: =IF(OR(G13="",G13="0",G13=0),0, IF(VALUE(LEFT(G13,FIND(":",G13)-1))<24,100, IF(VALUE(LEFT(G13,FIND(":",G13)-1))<48,50, IF(VALUE(LEFT(G13,FIND(":",G13)-1))<72,25,0)))) -> 100 | I13: =H13*2.5% -> 2.5 | J13: =(D13+H13)/2 -> 100 | K13: =J13*5% -> 5 | L13: R
A14: 11 | B14: K.D.Peta | C14: 23 | D14: =IF(L14="U", IF(C14>=35,100,ROUND(C14/35*100,2)), IF(L14="R", IF(C14>=21,100,ROUND(C14/21*100,2)), "" ) ) -> 100 | E14: =D14*2.5% -> 2.5 | F14: 0 days 00:43:21 | G14: =IF(OR(F14="",F14=0,LEFT(F14,1)="-"),0,TEXT((VALUE(LEFT(F14,FIND(" day",F14)-1))+TIMEVALUE(RIGHT(F14,8))),"[h]:mm:ss")) -> 0:43:21 | H14: =IF(OR(G14="",G14="0",G14=0),0, IF(VALUE(LEFT(G14,FIND(":",G14)-1))<24,100, IF(VALUE(LEFT(G14,FIND(":",G14)-1))<48,50, IF(VALUE(LEFT(G14,FIND(":",G14)-1))<72,25,0)))) -> 100 | I14: =H14*2.5% -> 2.5 | J14: =(D14+H14)/2 -> 100 | K14: =J14*5% -> 5 | L14: R
A15: 12 | B15: K.Kotapadu | C15: 23 | D15: =IF(L15="U", IF(C15>=35,100,ROUND(C15/35*100,2)), IF(L15="R", IF(C15>=21,100,ROUND(C15/21*100,2)), "" ) ) -> 100 | E15: =D15*2.5% -> 2.5 | F15: 0 days 00:43:21 | G15: =IF(OR(F15="",F15=0,LEFT(F15,1)="-"),0,TEXT((VALUE(LEFT(F15,FIND(" day",F15)-1))+TIMEVALUE(RIGHT(F15,8))),"[h]:mm:ss")) -> 0:43:21 | H15: =IF(OR(G15="",G15="0",G15=0),0, IF(VALUE(LEFT(G15,FIND(":",G15)-1))<24,100, IF(VALUE(LEFT(G15,FIND(":",G15)-1))<48,50, IF(VALUE(LEFT(G15,FIND(":",G15)-1))<72,25,0)))) -> 100 | I15: =H15*2.5% -> 2.5 | J15: =(D15+H15)/2 -> 100 | K15: =J15*5% -> 5 | L15: R
... A36: 33 | B36: Yelamanchili Traffic | C36: 22 | D36: =IF(L36="U", IF(C36>=35,100,ROUND(C36/35*100,2)), IF(L36="R", IF(C36>=21,100,ROUND(C36/21*100,2)), "" ) ) -> 100 | E36: =D36*2.5% -> 2.5 | F36: 0 days 00:43:21 | G36: =IF(OR(F36="",F36=0,LEFT(F36,1)="-"),0,TEXT((VALUE(LEFT(F36,FIND(" day",F36)-1))+TIMEVALUE(RIGHT(F36,8))),"[h]:mm:ss")) -> 0:43:21 | H36: =IF(OR(G36="",G36="0",G36=0),0, IF(VALUE(LEFT(G36,FIND(":",G36)-1))<24,100, IF(VALUE(LEFT(G36,FIND(":",G36)-1))<48,50, IF(VALUE(LEFT(G36,FIND(":",G36)-1))<72,25,0)))) -> 100 | I36: =H36*2.5% -> 2.5 | J36: =(D36+H36)/2 -> 100 | K36: =J36*5% -> 5 | L36: R

Sheet 16_APOLIS
A1: APOLIS - Mobile Application Downloads as on 15-09-2026 - (5 % - Marks)
A2: S.No | B2: Unit | C2: Total Employees | D2: No.of Mobile App Downloads | E2: APP Download Raw Value | F2: Marks for App (2.5) | G2: Total APRs Submitted | H2: APR Raw Value | I2: Marks for APR (2.5) | J2: Total Marks (5) | K2: Final Raw Value
A3: 1 | B3: A.Koduru | C3: 11 | D3: 11 | E3: =D3*100/C3 -> 100 | F3: =IFERROR(E3*2.5%,"") -> 2.5 | G3: 3 | H3: =IFERROR(G3*100/C3,"") -> 27.272727 | I3: =IFERROR(H3*2.5%,"") -> 0.68181818 | J3: =IFERROR(F3+I3,"") -> 3.1818182 | K3: =(E3+H3)/2 -> 63.636364
A4: 2 | B4: Anakapalli Rural | C4: 17 | D4: 17 | E4: =D4*100/C4 -> 100 | F4: =IFERROR(E4*2.5%,"") -> 2.5 | G4: 4 | H4: =IFERROR(G4*100/C4,"") -> 23.529412 | I4: =IFERROR(H4*2.5%,"") -> 0.58823529 | J4: =IFERROR(F4+I4,"") -> 3.0882353 | K4: =(E4+H4)/2 -> 61.764706
A5: 3 | B5: Anakapalli Town | C5: 60 | D5: 59 | E5: =D5*100/C5 -> 98.333333 | F5: =IFERROR(E5*2.5%,"") -> 2.4583333 | G5: 18 | H5: =IFERROR(G5*100/C5,"") -> 30 | I5: =IFERROR(H5*2.5%,"") -> 0.75 | J5: =IFERROR(F5+I5,"") -> 3.2083333 | K5: =(E5+H5)/2 -> 64.166667
A6: 4 | B6: Anakapalli Traffic | C6: 12 | D6: 12 | E6: =D6*100/C6 -> 100 | F6: =IFERROR(E6*2.5%,"") -> 2.5 | G6: 4 | H6: =IFERROR(G6*100/C6,"") -> 33.333333 | I6: =IFERROR(H6*2.5%,"") -> 0.83333333 | J6: =IFERROR(F6+I6,"") -> 3.3333333 | K6: =(E6+H6)/2 -> 66.666667
A7: 5 | B7: Atchutapuram | C7: 17 | D7: 17 | E7: =D7*100/C7 -> 100 | F7: =IFERROR(E7*2.5%,"") -> 2.5 | G7: 6 | H7: =IFERROR(G7*100/C7,"") -> 35.294118 | I7: =IFERROR(H7*2.5%,"") -> 0.88235294 | J7: =IFERROR(F7+I7,"") -> 3.3823529 | K7: =(E7+H7)/2 -> 67.647059
A8: 6 | B8: Butchiyyapeta | C8: 10 | D8: 10 | E8: =D8*100/C8 -> 100 | F8: =IFERROR(E8*2.5%,"") -> 2.5 | G8: 3 | H8: =IFERROR(G8*100/C8,"") -> 30 | I8: =IFERROR(H8*2.5%,"") -> 0.75 | J8: =IFERROR(F8+I8,"") -> 3.25 | K8: =(E8+H8)/2 -> 65
A9: 7 | B9: Cheedikada | C9: 9 | D9: 9 | E9: =D9*100/C9 -> 100 | F9: =IFERROR(E9*2.5%,"") -> 2.5 | G9: 2 | H9: =IFERROR(G9*100/C9,"") -> 22.222222 | I9: =IFERROR(H9*2.5%,"") -> 0.55555556 | J9: =IFERROR(F9+I9,"") -> 3.0555556 | K9: =(E9+H9)/2 -> 61.111111
A10: 8 | B10: Chodavaram | C10: 20 | D10: 20 | E10: =D10*100/C10 -> 100 | F10: =IFERROR(E10*2.5%,"") -> 2.5 | G10: 5 | H10: =IFERROR(G10*100/C10,"") -> 25 | I10: =IFERROR(H10*2.5%,"") -> 0.625 | J10: =IFERROR(F10+I10,"") -> 3.125 | K10: =(E10+H10)/2 -> 62.5
A11: 9 | B11: Devarapalli | C11: 10 | D11: 10 | E11: =D11*100/C11 -> 100 | F11: =IFERROR(E11*2.5%,"") -> 2.5 | G11: 3 | H11: =IFERROR(G11*100/C11,"") -> 30 | I11: =IFERROR(H11*2.5%,"") -> 0.75 | J11: =IFERROR(F11+I11,"") -> 3.25 | K11: =(E11+H11)/2 -> 65
A12: 10 | B12: Golugonda | C12: 10 | D12: 10 | E12: =D12*100/C12 -> 100 | F12: =IFERROR(E12*2.5%,"") -> 2.5 | G12: 3 | H12: =IFERROR(G12*100/C12,"") -> 30 | I12: =IFERROR(H12*2.5%,"") -> 0.75 | J12: =IFERROR(F12+I12,"") -> 3.25 | K12: =(E12+H12)/2 -> 65
A13: 11 | B13: K.D.Peta | C13: 8 | D13: 8 | E13: =D13*100/C13 -> 100 | F13: =IFERROR(E13*2.5%,"") -> 2.5 | G13: 2 | H13: =IFERROR(G13*100/C13,"") -> 25 | I13: =IFERROR(H13*2.5%,"") -> 0.625 | J13: =IFERROR(F13+I13,"") -> 3.125 | K13: =(E13+H13)/2 -> 62.5
A14: 12 | B14: K.Kotapadu | C14: 10 | D14: 10 | E14: =D14*100/C14 -> 100 | F14: =IFERROR(E14*2.5%,"") -> 2.5 | G14: 3 | H14: =IFERROR(G14*100/C14,"") -> 30 | I14: =IFERROR(H14*2.5%,"") -> 0.75 | J14: =IFERROR(F14+I14,"") -> 3.25 | K14: =(E14+H14)/2 -> 65
... A35: 33 | B35: Yelamanchili Traffic | C35: 8 | D35: 8 | E35: =D35*100/C35 -> 100 | F35: =IFERROR(E35*2.5%,"") -> 2.5 | G35: 2 | H35: =IFERROR(G35*100/C35,"") -> 25 | I35: =IFERROR(H35*2.5%,"") -> 0.625 | J35: =IFERROR(F35+I35,"") -> 3.125 | K35: =(E35+H35)/2 -> 62.5
A36: Total | C36: =SUM(C3:C35) -> 513 | D36: =SUM(D3:D35) -> 509 | E36: =AVERAGE(E3:E35) -> 99.506845 | F36: =AVERAGE(F3:F35) -> 2.4876711 | G36: =SUM(G3:G35) -> 148 | H36: =AVERAGE(H3:H35) -> 29.15746 | I36: =SUM(I3:I35) -> 24.054905 | J36: =SUM(J3:J35) -> 106.14805 | K36: =SUM(K3:K35) -> 2122.961

Sheet 17_DRONE_FLYING
A1: DRONE FLYING HOURSFROM 09-09-2026 TO 15-09-2026 - (5 % Marks)
A2: S.No | B2: PS | C2: Is Drone Available | D2: Hours | E2: Min | F2: Sec | G2: Total Seconds | H2: Flying Value (80%) | I2: Enforce ment ( 20%) | J2: Raw Value | K2: Marks | L2: Reamrks
A3: 1 | B3: A.Koduru | C3: NO | D3: 6 | G3: =IF((D3*3600+E3*60+F3)=0,-1,D3*3600+E3*60+F3) -> 21600 | H3: =IF(AND(C3="NO",D3=0),20,IF(G3>=126000,80,IF(G3>0,ROUND(20+(G3/126000)*60,0),20))) -> 30 | I3: 20 | J3: =H3+I3 -> 50 | K3: =J3*5% -> 2.5 | L3: Gambling -1
A4: 2 | B4: Anakapalli Rural | C4: YES | D4: 10 | G4: =IF((D4*3600+E4*60+F4)=0,-1,D4*3600+E4*60+F4) -> 36000 | H4: =IF(AND(C4="NO",D4=0),20,IF(G4>=126000,80,IF(G4>0,ROUND(20+(G4/126000)*60,0),20))) -> 37 | I4: 20 | J4: =H4+I4 -> 57 | K4: =J4*5% -> 2.85 | L4: Opend Drinking 2
A5: 3 | B5: Anakapalli Town | C5: YES | D5: 12 | G5: =IF((D5*3600+E5*60+F5)=0,-1,D5*3600+E5*60+F5) -> 43200 | H5: =IF(AND(C5="NO",D5=0),20,IF(G5>=126000,80,IF(G5>0,ROUND(20+(G5/126000)*60,0),20))) -> 41 | I5: 20 | J5: =H5+I5 -> 61 | K5: =J5*5% -> 3.05 | L5: open driking 4
A6: 4 | B6: Anakapalli Traffic | C6: YES | D6: 12 | G6: =IF((D6*3600+E6*60+F6)=0,-1,D6*3600+E6*60+F6) -> 43200 | H6: =IF(AND(C6="NO",D6=0),20,IF(G6>=126000,80,IF(G6>0,ROUND(20+(G6/126000)*60,0),20))) -> 41 | I6: 20 | J6: =H6+I6 -> 61 | K6: =J6*5% -> 3.05 | L6: open drinking 2
A7: 5 | B7: Atchutapuram | C7: YES | D7: 18 | G7: =IF((D7*3600+E7*60+F7)=0,-1,D7*3600+E7*60+F7) -> 64800 | H7: =IF(AND(C7="NO",D7=0),20,IF(G7>=126000,80,IF(G7>0,ROUND(20+(G7/126000)*60,0),20))) -> 51 | J7: =H7+I7 -> 51 | K7: =J7*5% -> 2.55 | L7: Open drinking 4
A8: 6 | B8: Butchiyyapeta | C8: NO | D8: 18 | G8: =IF((D8*3600+E8*60+F8)=0,-1,D8*3600+E8*60+F8) -> 64800 | H8: =IF(AND(C8="NO",D8=0),20,IF(G8>=126000,80,IF(G8>0,ROUND(20+(G8/126000)*60,0),20))) -> 51 | J8: =H8+I8 -> 51 | K8: =J8*5% -> 2.55 | L8: Missing Case Traced
A9: 7 | B9: Cheedikada | C9: NO | D9: 18 | G9: =IF((D9*3600+E9*60+F9)=0,-1,D9*3600+E9*60+F9) -> 64800 | H9: =IF(AND(C9="NO",D9=0),20,IF(G9>=126000,80,IF(G9>0,ROUND(20+(G9/126000)*60,0),20))) -> 51 | J9: =H9+I9 -> 51 | K9: =J9*5% -> 2.55 | L9: Gambling -1
A10: 8 | B10: Chodavaram | C10: YES | D10: 18 | G10: =IF((D10*3600+E10*60+F10)=0,-1,D10*3600+E10*60+F10) -> 64800 | H10: =IF(AND(C10="NO",D10=0),20,IF(G10>=126000,80,IF(G10>0,ROUND(20+(G10/126000)*60,0),20))) -> 51 | J10: =H10+I10 -> 51 | K10: =J10*5% -> 2.55 | L10: open drinking 1
A11: 9 | B11: Devarapalli | C11: NO | D11: 18 | G11: =IF((D11*3600+E11*60+F11)=0,-1,D11*3600+E11*60+F11) -> 64800 | H11: =IF(AND(C11="NO",D11=0),20,IF(G11>=126000,80,IF(G11>0,ROUND(20+(G11/126000)*60,0),20))) -> 51 | J11: =H11+I11 -> 51 | K11: =J11*5% -> 2.55
A12: 10 | B12: Golugonda | C12: NO | D12: 18 | G12: =IF((D12*3600+E12*60+F12)=0,-1,D12*3600+E12*60+F12) -> 64800 | H12: =IF(AND(C12="NO",D12=0),20,IF(G12>=126000,80,IF(G12>0,ROUND(20+(G12/126000)*60,0),20))) -> 51 | J12: =H12+I12 -> 51 | K12: =J12*5% -> 2.55
A13: 11 | B13: K.D.Peta | C13: YES | D13: 18 | G13: =IF((D13*3600+E13*60+F13)=0,-1,D13*3600+E13*60+F13) -> 64800 | H13: =IF(AND(C13="NO",D13=0),20,IF(G13>=126000,80,IF(G13>0,ROUND(20+(G13/126000)*60,0),20))) -> 51 | J13: =H13+I13 -> 51 | K13: =J13*5% -> 2.55
A14: 12 | B14: K.Kotapadu | C14: YES | D14: 18 | G14: =IF((D14*3600+E14*60+F14)=0,-1,D14*3600+E14*60+F14) -> 64800 | H14: =IF(AND(C14="NO",D14=0),20,IF(G14>=126000,80,IF(G14>0,ROUND(20+(G14/126000)*60,0),20))) -> 51 | J14: =H14+I14 -> 51 | K14: =J14*5% -> 2.55
A15: 13 | B15: Kasimkota | C15: YES | D15: 18 | G15: =IF((D15*3600+E15*60+F15)=0,-1,D15*3600+E15*60+F15) -> 64800 | H15: =IF(AND(C15="NO",D15=0),20,IF(G15>=126000,80,IF(G15>0,ROUND(20+(G15/126000)*60,0),20))) -> 51 | J15: =H15+I15 -> 51 | K15: =J15*5% -> 2.55
A16: 14 | B16: Kotavurtla | C16: NO | D16: 20 | G16: =IF((D16*3600+E16*60+F16)=0,-1,D16*3600+E16*60+F16) -> 72000 | H16: =IF(AND(C16="NO",D16=0),20,IF(G16>=126000,80,IF(G16>0,ROUND(20+(G16/126000)*60,0),20))) -> 54 | J16: =H16+I16 -> 54 | K16: =J16*5% -> 2.7
A17: 15 | B17: Kothakota | C17: YES | D17: 18 | G17: =IF((D17*3600+E17*60+F17)=0,-1,D17*3600+E17*60+F17) -> 64800 | H17: =IF(AND(C17="NO",D17=0),20,IF(G17>=126000,80,IF(G17>0,ROUND(20+(G17/126000)*60,0),20))) -> 51 | J17: =H17+I17 -> 51 | K17: =J17*5% -> 2.55
A18: 16 | B18: Mahila UPS, Anakapalli | C18: NO | D18: 18 | G18: =IF((D18*3600+E18*60+F18)=0,-1,D18*3600+E18*60+F18) -> 64800 | H18: =IF(AND(C18="NO",D18=0),20,IF(G18>=126000,80,IF(G18>0,ROUND(20+(G18/126000)*60,0),20))) -> 51 | J18: =H18+I18 -> 51 | K18: =J18*5% -> 2.55
A19: 17 | B19: Makavarapalem | C19: YES | D19: 18 | G19: =IF((D19*3600+E19*60+F19)=0,-1,D19*3600+E19*60+F19) -> 64800 | H19: =IF(AND(C19="NO",D19=0),20,IF(G19>=126000,80,IF(G19>0,ROUND(20+(G19/126000)*60,0),20))) -> 51 | J19: =H19+I19 -> 51 | K19: =J19*5% -> 2.55
A20: 18 | B20: Munagapaka | C20: NO | D20: 18 | G20: =IF((D20*3600+E20*60+F20)=0,-1,D20*3600+E20*60+F20) -> 64800 | H20: =IF(AND(C20="NO",D20=0),20,IF(G20>=126000,80,IF(G20>0,ROUND(20+(G20/126000)*60,0),20))) -> 51 | J20: =H20+I20 -> 51 | K20: =J20*5% -> 2.55
A21: 19 | B21: Nakkapalli | C21: YES | D21: 18 | G21: =IF((D21*3600+E21*60+F21)=0,-1,D21*3600+E21*60+F21) -> 64800 | H21: =IF(AND(C21="NO",D21=0),20,IF(G21>=126000,80,IF(G21>0,ROUND(20+(G21/126000)*60,0),20))) -> 51 | J21: =H21+I21 -> 51 | K21: =J21*5% -> 2.55
A22: 20 | B22: Narsipatnam Rural | C22: YES | D22: 20 | G22: =IF((D22*3600+E22*60+F22)=0,-1,D22*3600+E22*60+F22) -> 72000 | H22: =IF(AND(C22="NO",D22=0),20,IF(G22>=126000,80,IF(G22>0,ROUND(20+(G22/126000)*60,0),20))) -> 54 | J22: =H22+I22 -> 54 | K22: =J22*5% -> 2.7
... A35: 33 | B35: Yelamanchili Traffic | C35: YES | D35: 20 | G35: =IF((D35*3600+E35*60+F35)=0,-1,D35*3600+E35*60+F35) -> 72000 | H35: =IF(AND(C35="NO",D35=0),20,IF(G35>=126000,80,IF(G35>0,ROUND(20+(G35/126000)*60,0),20))) -> 54 | J35: =H35+I35 -> 54 | K35: =J35*5% -> 2.7

Sheet 18_112_TABS
A1: DIAL 112 TABS WORKING INFORMATION FROM 09-09-2026 TO 15-09-2026 - (5 % Marks)
A2: S.No | B2: PS | C2: Total Tabs Config | D2: ERU Connected Live | E2: Dis-connected Tabs | F2: % of Disconnected Tabs | G2: Raw Value | H2: Marks
A3: 1 | B3: A.Koduru | C3: 2 | D3: 2 | E3: 0 | F3: =IF(C3=0,0,E3/C3*100) -> 0 | G3: =IF(C3=0,100,(D3/C3)*100) -> 100 | H3: =G3*5% -> 5
A4: 2 | B4: Anakapalli Rural | C4: 3 | D4: 3 | E4: 0 | F4: =IF(C4=0,0,E4/C4*100) -> 0 | G4: =IF(C4=0,100,(D4/C4)*100) -> 100 | H4: =G4*5% -> 5
A5: 3 | B5: Anakapalli Town | C5: 5 | D5: 5 | E5: 0 | F5: =IF(C5=0,0,E5/C5*100) -> 0 | G5: =IF(C5=0,100,(D5/C5)*100) -> 100 | H5: =G5*5% -> 5
A6: 4 | B6: Anakapalli Traffic | C6: 3 | D6: 3 | E6: 0 | F6: =IF(C6=0,0,E6/C6*100) -> 0 | G6: =IF(C6=0,100,(D6/C6)*100) -> 100 | H6: =G6*5% -> 5
A7: 5 | B7: Atchutapuram | C7: 3 | D7: 3 | E7: 0 | F7: =IF(C7=0,0,E7/C7*100) -> 0 | G7: =IF(C7=0,100,(D7/C7)*100) -> 100 | H7: =G7*5% -> 5
A8: 6 | B8: Butchiyyapeta | C8: 2 | D8: 2 | E8: 0 | F8: =IF(C8=0,0,E8/C8*100) -> 0 | G8: =IF(C8=0,100,(D8/C8)*100) -> 100 | H8: =G8*5% -> 5
A9: 7 | B9: Cheedikada | C9: 2 | D9: 2 | E9: 0 | F9: =IF(C9=0,0,E9/C9*100) -> 0 | G9: =IF(C9=0,100,(D9/C9)*100) -> 100 | H9: =G9*5% -> 5
A10: 8 | B10: Chodavaram | C10: 2 | D10: 2 | E10: 0 | F10: =IF(C10=0,0,E10/C10*100) -> 0 | G10: =IF(C10=0,100,(D10/C10)*100) -> 100 | H10: =G10*5% -> 5
A11: 9 | B11: Devarapalli | C11: 2 | D11: 2 | E11: 0 | F11: =IF(C11=0,0,E11/C11*100) -> 0 | G11: =IF(C11=0,100,(D11/C11)*100) -> 100 | H11: =G11*5% -> 5
A12: 10 | B12: Golugonda | C12: 2 | D12: 2 | E12: 0 | F12: =IF(C12=0,0,E12/C12*100) -> 0 | G12: =IF(C12=0,100,(D12/C12)*100) -> 100 | H12: =G12*5% -> 5
A13: 11 | B13: K.D.Peta | C13: 3 | D13: 1 | E13: 2 | F13: =IF(C13=0,0,E13/C13*100) -> 66.666667 | G13: =IF(C13=0,100,(D13/C13)*100) -> 33.333333 | H13: =G13*5% -> 1.6666667
A14: 12 | B14: K.Kotapadu | C14: 2 | D14: 1 | E14: 1 | F14: =IF(C14=0,0,E14/C14*100) -> 50 | G14: =IF(C14=0,100,(D14/C14)*100) -> 50 | H14: =G14*5% -> 2.5
... A35: 33 | B35: Yelamanchili Traffic | C35: 1 | D35: 1 | E35: 0 | F35: =IF(C35=0,0,E35/C35*100) -> 0 | G35: =IF(C35=0,100,(D35/C35)*100) -> 100 | H35: =G35*5% -> 5
A36: TOTAL | C36: =SUM(C3:C35) -> 82 | D36: =SUM(D3:D35) -> 77 | E36: =SUM(E3:E35) -> 5 | F36: =AVERAGE(F3:F35) -> 5.8080808 | G36: =AVERAGE(G3:G35) -> 94.191919 | H36: =AVERAGE(H3:H35) -> 4.709596

Sheet 19_DIAL100_RES
A1: DIAL 112 AVERAGE RESPONSE TIME FROM 09-09-2026 TO 15-09-2026 - (5 % Marks)
A2: S.No | B2: PS | C2: Total calls Assigned to PS | D2: No. of Calls Assigned to Tabs by PS | E2: No. of Calls not Assigned to Tabs by PS | F2: Average Response Time (HH:MM:SS) | G2: Raw Value | H2: Marks
A3: 1 | B3: A.Koduru | C3: 1 | D3: 1 | E3: 0 | F3: 00.00.44 | G3: {=IF(C3=0,50,100-((TIMEVALUE(SUBSTITUTE(F3,".",":"))-MIN(IF($C$3:$C$35>0,TIMEVALUE(SUBSTITUTE($F$3:$F$35,".",":")))))/(MAX(IF($C$3:$C$35>0,TIMEVALUE(SUBSTITUTE($F$3:$F$35,".",":"))))-MIN(IF($C$3:$C$35>0,TIMEVALUE(SUBSTITUTE($F$3:$F$35,".",":"))))))*100)} -> 96.371882 | H3: =G3*5% -> 4.8185941
A4: 2 | B4: Anakapalli Rural | C4: 20 | D4: 20 | E4: 0 | F4: 00.03.13 | G4: {=IF(C4=0,50,100-((TIMEVALUE(SUBSTITUTE(F4,".",":"))-MIN(IF($C$3:$C$35>0,TIMEVALUE(SUBSTITUTE($F$3:$F$35,".",":")))))/(MAX(IF($C$3:$C$35>0,TIMEVALUE(SUBSTITUTE($F$3:$F$35,".",":"))))-MIN(IF($C$3:$C$35>0,TIMEVALUE(SUBSTITUTE($F$3:$F$35,".",":"))))))*100)} -> 62.585034 | H4: =G4*5% -> 3.1292517
A5: 3 | B5: Anakapalli Town | C5: 38 | D5: 38 | E5: 0 | F5: 00.02.57 | G5: {=IF(C5=0,50,100-((TIMEVALUE(SUBSTITUTE(F5,".",":"))-MIN(IF($C$3:$C$35>0,TIMEVALUE(SUBSTITUTE($F$3:$F$35,".",":")))))/(MAX(IF($C$3:$C$35>0,TIMEVALUE(SUBSTITUTE($F$3:$F$35,".",":"))))-MIN(IF($C$3:$C$35>0,TIMEVALUE(SUBSTITUTE($F$3:$F$35,".",":"))))))*100)} -> 66.213152 | H5: =G5*5% -> 3.3106576
